Workbook

Sheet 无任命人员话费福利
A1: 2026年内蒙古准格尔旗力量煤业有限公司 无任命人员话费及燃油费报销台账
A2: 序号 | B2: 类别 | C2: 姓名 | D2: 身份证号 | E2: 工作部门 | F2: 岗位 | G2: 话费报销情况 | L2: 燃油报销情况 | P2: 备注 | S2: 电话费 | AE2: 探亲地 | AF2: 第一次探亲 | AI2: 第二次探亲 | AL2: 第三次探亲 | AO2: 第四次探亲 | AR2: 第五次探亲 | AU2: 第六次探亲 | AX2: 探亲费 总金额 | AY2: 报销合计 金额 | AZ2: 备案日期 | BA2: 经办人 | BB2: 备注
C3: 姓名 | D3: 身份证号 | E3: 工作部门 | F3: 岗位 | G3: 话费开始报销月份 | H3: 报销依据 | I3: 话费申请标准（元/月） | J3: 已执行标准（元/月） | K3: 建议调整标准 （元/月） | L3: 燃油标准（元/月） | M3: 最终审批人 | N3: 是否有扫描件 | O3: 审批时间 | S3: 1月 | T3: 2月 | U3: 3月 | V3: 4月 | W3: 5月 | X3: 6月 | Y3: 7月 | Z3: 8月 | AA3: 9月 | AB3: 10月 | AC3: 11月 | AD3: 12月 | AF3: 开始时间 | AG3: 结束时间 | AH3: 金额 | AI3: 开始时间 | AJ3: 结束时间 | AK3: 金额 | AL3: 开始时间 | AM3: 结束时间 | AN3: 金额 | AO3: 开始时间 | AP3: 结束时间 | AQ3: 金额 | AR3: 开始时间 | AS3: 结束时间 | AT3: 金额 | AU3: 开始时间 | AV3: 结束时间 | AW3: 金额
A4: 1 | C4: 许燕 | D4: =VLOOKUP(C4,[2]在职人员信息表!$F:$U,16,FALSE) -> 152723199105241520 | E4: =VLOOKUP(C4,[1]在职人员信息表!$F:$G,2,FALSE) -> 总调度室 | F4: =VLOOKUP(C4,[1]在职人员信息表!$F:$H,3,FALSE) -> 办事员 | G4: 44378 | H4: 请示审批报销 | I4: 100 | M4: 李波 | N4: 有 | O4: 44424 | R4: =_xlfn.XLOOKUP(C4,'[4]20250916话费报销调整'!$B:$B,'[4]20250916话费报销调整'!$D:$D,0,0) -> 0 | S4: 100 | T4: 100 | U4: 100
A5: 2 | C5: 白晶晶 | D5: =VLOOKUP(C5,[2]在职人员信息表!$F:$U,16,FALSE) -> 150422198502193949 | E5: =VLOOKUP(C5,[1]在职人员信息表!$F:$G,2,FALSE) -> 安全监察科 | F5: =VLOOKUP(C5,[1]在职人员信息表!$F:$H,3,FALSE) -> 资料员 | G5: 44378 | H5: 请示审批报销 | I5: 100 | M5: 李运成 | N5: 有 | O5: 44305 | Q5: =_xlfn.XLOOKUP(C5,[3]调动人员明细表!$D:$D,[3]调动人员明细表!$F:$F,0,0) -> 44261 | R5: =_xlfn.XLOOKUP(C5,'[4]20250916话费报销调整'!$B:$B,'[4]20250916话费报销调整'!$D:$D,0,0) -> 0 | S5: 99.6 | T5: 99 | U5: 99.2
A6: 3 | C6: 张娜 | D6: =VLOOKUP(C6,[2]在职人员信息表!$F:$U,16,FALSE) -> 150207198702241023 | E6: =VLOOKUP(C6,[1]在职人员信息表!$F:$G,2,FALSE) -> 机运队 | F6: =VLOOKUP(C6,[1]在职人员信息表!$F:$H,3,FALSE) -> 办事员 | G6: 43466 | H6: 请示审批报销 | I6: 100 | M6: 李波 | N6: 有 | O6: 45182 | R6: =_xlfn.XLOOKUP(C6,'[4]20250916话费报销调整'!$B:$B,'[4]20250916话费报销调整'!$D:$D,0,0) -> 0 | S6: 100 | T6: 100 | U6: 100
A7: 4 | C7: 张衡 | D7: =VLOOKUP(C7,[2]在职人员信息表!$F:$U,16,FALSE) -> 152633197402282714 | E7: =VLOOKUP(C7,[1]在职人员信息表!$F:$G,2,FALSE) -> 生产机修科 | F7: =VLOOKUP(C7,[1]在职人员信息表!$F:$H,3,FALSE) -> 专员 | G7: 44348 | H7: 请示审批报销 | I7: 100 | M7: 李波 | N7: 有 | O7: 44432 | P7: 2025年8月调动，调动后无审批 | Q7: =_xlfn.XLOOKUP(C7,[3]调动人员明细表!$D:$D,[3]调动人员明细表!$F:$F,0,0) -> 45884 | R7: =_xlfn.XLOOKUP(C7,'[4]20250916话费报销调整'!$B:$B,'[4]20250916话费报销调整'!$D:$D,0,0) -> 原请示对应标准（未明确具体金额） | S7: 100 | T7: 100 | U7: 100
A8: 5 | C8: 高文豹 | D8: 152723198909051234 | E8: 开发部 | F8: 主管 | G8: 45170 | H8: 请示审批报销 | I8: 150 | J8: 150 | K8: 200 | L8: 1000 | M8: 李波 | O8: 45149 | P8: 面试审批岗位为主管 | R8: =_xlfn.XLOOKUP(C8,'[4]20250916话费报销调整'!$B:$B,'[4]20250916话费报销调整'!$D:$D,0,0) -> 0 | S8: 150 | T8: 150 | U8: 150
A9: 6 | C9: 田海霞 | D9: =VLOOKUP(C9,[2]在职人员信息表!$F:$U,16,FALSE) -> 15272319900930152X | E9: =VLOOKUP(C9,[1]在职人员信息表!$F:$G,2,FALSE) -> 开发部 | F9: =VLOOKUP(C9,[1]在职人员信息表!$F:$H,3,FALSE) -> 专员 | G9: 43525 | H9: 请示审批报销 | I9: 200 | L9: 1000 | M9: 具文忠 | N9: 有 | O9: 43525 | R9: =_xlfn.XLOOKUP(C9,'[4]20250916话费报销调整'!$B:$B,'[4]20250916话费报销调整'!$D:$D,0,0) -> 0 | S9: 158 | T9: 158 | U9: 168.5
A10: 7 | C10: 王鸿 | D10: =VLOOKUP(C10,[2]在职人员信息表!$F:$U,16,FALSE) -> 152723198512064512 | E10: =VLOOKUP(C10,[1]在职人员信息表!$F:$G,2,FALSE) -> 开发部 | F10: =VLOOKUP(C10,[1]在职人员信息表!$F:$H,3,FALSE) -> 专员 | G10: 44378 | H10: 请示审批报销 | I10: 200 | L10: 1000 | M10: 李波 | N10: 有 | O10: 44411 | R10: =_xlfn.XLOOKUP(C10,'[4]20250916话费报销调整'!$B:$B,'[4]20250916话费报销调整'!$D:$D,0,0) -> 0 | S10: 145.2 | T10: 144.4 | U10: 176.5
A11: 8 | C11: 张雄 | D11: =VLOOKUP(C11,[2]在职人员信息表!$F:$U,16,FALSE) -> 152723199111250618 | E11: =VLOOKUP(C11,[1]在职人员信息表!$F:$G,2,FALSE) -> 采购部 | F11: =VLOOKUP(C11,[1]在职人员信息表!$F:$H,3,FALSE) -> 采购专员 | G11: 44743 | H11: 请示审批报销 | I11: 200 | J11: 200 | K11: 200 | M11: 李波 | N11: 有 | O11: 44753 | P11: 2025年6月调动，调动后有审批 | Q11: =_xlfn.XLOOKUP(C11,[3]调动人员明细表!$D:$D,[3]调动人员明细表!$F:$F,0,0) -> 44738 | R11: =_xlfn.XLOOKUP(C11,'[4]20250916话费报销调整'!$B:$B,'[4]20250916话费报销调整'!$D:$D,0,0) -> 100-150元/月
A12: 9 | C12: 周瑞峰 | D12: =VLOOKUP(C12,[2]在职人员信息表!$F:$U,16,FALSE) -> 152723198911160915 | E12: =VLOOKUP(C12,[1]在职人员信息表!$F:$G,2,FALSE) -> 采购部 | F12: =VLOOKUP(C12,[1]在职人员信息表!$F:$H,3,FALSE) -> 采购专员 | G12: 44317 | H12: 请示审批报销 | I12: 200 | J12: 200 | M12: 李波 | N12: 有 | O12: 45791 | Q12: =_xlfn.XLOOKUP(C12,[3]调动人员明细表!$D:$D,[3]调动人员明细表!$F:$F,0,0) -> 44317 | R12: =_xlfn.XLOOKUP(C12,'[4]20250916话费报销调整'!$B:$B,'[4]20250916话费报销调整'!$D:$D,0,0) -> 0
A13: 10 | C13: 白杰铭 | D13: =VLOOKUP(C13,[2]在职人员信息表!$F:$U,16,FALSE) -> 15272319921116811X | E13: =VLOOKUP(C13,[1]在职人员信息表!$F:$G,2,FALSE) -> 采购部 | F13: =VLOOKUP(C13,[1]在职人员信息表!$F:$H,3,FALSE) -> 采购专员 | G13: 44013 | H13: 请示审批报销 | I13: 200 | J13: 200 | M13: 李波 | N13: 有 | O13: 44033 | R13: =_xlfn.XLOOKUP(C13,'[4]20250916话费报销调整'!$B:$B,'[4]20250916话费报销调整'!$D:$D,0,0) -> 0
A14: 11 | C14: 武丽婷 | D14: =VLOOKUP(C14,[2]在职人员信息表!$F:$U,16,FALSE) -> 142229199307233122 | E14: =VLOOKUP(C14,[1]在职人员信息表!$F:$G,2,FALSE) -> 采购部 | F14: =VLOOKUP(C14,[1]在职人员信息表!$F:$H,3,FALSE) -> 供应商管理员 | G14: 43709 | H14: 请示审批报销 | I14: 150 | J14: 200 | K14: 200 | M14: 具文忠 | N14: 有 | O14: 43009 | R14: =_xlfn.XLOOKUP(C14,'[4]20250916话费报销调整'!$B:$B,'[4]20250916话费报销调整'!$D:$D,0,0) -> 100-150元/月
A15: 12 | C15: 鲁佩琴 | D15: =VLOOKUP(C15,[2]在职人员信息表!$F:$U,16,FALSE) -> 15272319920602092X | E15: =VLOOKUP(C15,[1]在职人员信息表!$F:$G,2,FALSE) -> 采购部 | F15: 专员 | G15: 44228 | H15: 请示审批报销 | I15: 100 | J15: 200 | K15: 200 | M15: 李波 | N15: 有 | O15: 44235 | P15: 2024年12月调动，调动后无审批 | Q15: =_xlfn.XLOOKUP(C15,[3]调动人员明细表!$D:$D,[3]调动人员明细表!$F:$F,0,0) -> 45636 | R15: =_xlfn.XLOOKUP(C15,'[4]20250916话费报销调整'!$B:$B,'[4]20250916话费报销调整'!$D:$D,0,0) -> 100-150元/月
A16: 13 | C16: 蔺昱恺 | D16: =VLOOKUP(C16,[2]在职人员信息表!$F:$U,16,FALSE) -> 152722200001226114 | E16: =VLOOKUP(C16,[1]在职人员信息表!$F:$G,2,FALSE) -> 人力行政中心 | F16: =VLOOKUP(C16,[1]在职人员信息表!$F:$H,3,FALSE) -> 专员 | G16: 45078 | H16: 请示审批报销 | I16: 200 | M16: 李波 | O16: 45230 | Q16: =_xlfn.XLOOKUP(C16,[3]调动人员明细表!$D:$D,[3]调动人员明细表!$F:$F,0,0) -> 45054 | R16: =_xlfn.XLOOKUP(C16,'[4]20250916话费报销调整'!$B:$B,'[4]20250916话费报销调整'!$D:$D,0,0) -> 0
A17: 14 | C17: 王强 | D17: =VLOOKUP(C17,[2]在职人员信息表!$F:$U,16,FALSE) -> 140224198310217811 | E17: 人力行政中心 | F17: 工程师 | G17: 44470 | H17: 请示审批报销 | I17: 150 | M17: 李波 | N17: 有 | O17: 44544 | R17: =_xlfn.XLOOKUP(C17,'[4]20250916话费报销调整'!$B:$B,'[4]20250916话费报销调整'!$D:$D,0,0) -> 0
A18: 15 | C18: 杨钰珍 | D18: =VLOOKUP(C18,[2]在职人员信息表!$F:$U,16,FALSE) -> 130426199702100328 | E18: =VLOOKUP(C18,[1]在职人员信息表!$F:$G,2,FALSE) -> 人力行政中心 | F18: =VLOOKUP(C18,[1]在职人员信息表!$F:$H,3,FALSE) -> 专员 | G18: 43647 | H18: 请示审批报销 | I18: 100 | J18: 100 | K18: 150 | M18: 具文忠 | N18: 有 | O18: 43650 | P18: 2024年4月调动，调动后无审批 | Q18: =_xlfn.XLOOKUP(C18,[3]调动人员明细表!$D:$D,[3]调动人员明细表!$F:$F,0,0) -> 45385 | R18: =_xlfn.XLOOKUP(C18,'[4]20250916话费报销调整'!$B:$B,'[4]20250916话费报销调整'!$D:$D,0,0) -> 0
A19: 16 | C19: 胡建广 | D19: =VLOOKUP(C19,[2]在职人员信息表!$F:$U,16,FALSE) -> 142625198209092110 | E19: =VLOOKUP(C19,[1]在职人员信息表!$F:$G,2,FALSE) -> 经营管理部 | F19: =VLOOKUP(C19,[1]在职人员信息表!$F:$H,3,FALSE) -> 预算员 | G19: 44835 | H19: 请示审批报销 | I19: 150 | M19: 李运成 | N19: 有 | O19: 44875 | R19: =_xlfn.XLOOKUP(C19,'[4]20250916话费报销调整'!$B:$B,'[4]20250916话费报销调整'!$D:$D,0,0) -> 0 | S19: 150 | T19: 150 | U19: 150
A20: 17 | C20: 李山山 | D20: =VLOOKUP(C20,[2]在职人员信息表!$F:$U,16,FALSE) -> 130427199006082775 | E20: =VLOOKUP(C20,[1]在职人员信息表!$F:$G,2,FALSE) -> 生产机修科 | F20: =VLOOKUP(C20,[1]在职人员信息表!$F:$H,3,FALSE) -> 专员 | G20: 44835 | H20: 请示审批报销 | I20: 150 | M20: 李波 | N20: 有 | O20: 44669 | P20: 2024年10月调动，调动后无审批 | Q20: =_xlfn.XLOOKUP(C20,[3]调动人员明细表!$D:$D,[3]调动人员明细表!$F:$F,0,0) -> 45580 | R20: =_xlfn.XLOOKUP(C20,'[4]20250916话费报销调整'!$B:$B,'[4]20250916话费报销调整'!$D:$D,0,0) -> 原请示对应标准（未明确具体金额）
A21: 18 | C21: 蔺向龙 | D21: =VLOOKUP(C21,[2]在职人员信息表!$F:$U,16,FALSE) -> 152723198703235716 | E21: =VLOOKUP(C21,[1]在职人员信息表!$F:$G,2,FALSE) -> 复垦绿化队 | F21: =VLOOKUP(C21,[1]在职人员信息表!$F:$H,3,FALSE) -> 专员 | G21: 44835 | H21: 请示审批报销 | I21: 100 | M21: 李运成 | N21: 有 | O21: 45040 | R21: =_xlfn.XLOOKUP(C21,'[4]20250916话费报销调整'!$B:$B,'[4]20250916话费报销调整'!$D:$D,0,0) -> 100元/月 | S21: 100 | T21: 100 | U21: 100
A22: 19 | C22: 白龙 | D22: =VLOOKUP(C22,[2]在职人员信息表!$F:$U,16,FALSE) -> 152723199609112415 | E22: =VLOOKUP(C22,[1]在职人员信息表!$F:$G,2,FALSE) -> 经营管理部 | F22: =VLOOKUP(C22,[1]在职人员信息表!$F:$H,3,FALSE) -> 专员 | G22: 45597 | H22: 请示审批报销 | I22: 200 | M22: 李波 | N22: 有 | O22: 45630 | P22: 2024年11月调动，调动后有审批 | Q22: =_xlfn.XLOOKUP(C22,[3]调动人员明细表!$D:$D,[3]调动人员明细表!$F:$F,0,0) -> 45608 | R22: =_xlfn.XLOOKUP(C22,'[4]20250916话费报销调整'!$B:$B,'[4]20250916话费报销调整'!$D:$D,0,0) -> 0 | S22: 175.85 | T22: 178.58 | U22: 175.12
A23: 20 | C23: 朱彦飞 | D23: =VLOOKUP(C23,[2]在职人员信息表!$F:$U,16,FALSE) -> 152723199705152118 | E23: =VLOOKUP(C23,[1]在职人员信息表!$F:$G,2,FALSE) -> 复垦绿化队 | F23: =VLOOKUP(C23,[1]在职人员信息表!$F:$H,3,FALSE) -> 专员 | G23: 44378 | H23: 请示审批报销 | I23: 200 | K23: 0 | L23: 1000 | M23: 李波 | N23: 有 | O23: 44385 | P23: 2025年8月调动，调动后建议取消 | Q23: =_xlfn.XLOOKUP(C23,[3]调动人员明细表!$D:$D,[3]调动人员明细表!$F:$F,0,0) -> 45887 | R23: =_xlfn.XLOOKUP(C23,'[4]20250916话费报销调整'!$B:$B,'[4]20250916话费报销调整'!$D:$D,0,0) -> 原请示对应标准（未明确具体金额）
A24: 21 | C24: 刘向龙 | D24: =VLOOKUP(C24,[2]在职人员信息表!$F:$U,16,FALSE) -> 152723199505197215 | E24: =VLOOKUP(C24,[1]在职人员信息表!$F:$G,2,FALSE) -> 人力行政中心 | F24: =VLOOKUP(C24,[1]在职人员信息表!$F:$H,3,FALSE) -> 司机班长 | G24: 44287 | H24: 司机限额200 | I24: 200 | M24: 司机无请示 | R24: =_xlfn.XLOOKUP(C24,'[4]20250916话费报销调整'!$B:$B,'[4]20250916话费报销调整'!$D:$D,0,0) -> 0
A25: 22 | C25: 张志光 | D25: =VLOOKUP(C25,[2]在职人员信息表!$F:$U,16,FALSE) -> 150124198403191717 | E25: =VLOOKUP(C25,[1]在职人员信息表!$F:$G,2,FALSE) -> 人力行政中心 | F25: =VLOOKUP(C25,[1]在职人员信息表!$F:$H,3,FALSE) -> 司机 | G25: 44197 | H25: 司机限额200 | I25: 200 | M25: 司机无请示 | R25: =_xlfn.XLOOKUP(C25,'[4]20250916话费报销调整'!$B:$B,'[4]20250916话费报销调整'!$D:$D,0,0) -> 0
A26: 23 | C26: 张志强 | D26: =VLOOKUP(C26,[2]在职人员信息表!$F:$U,16,FALSE) -> 152723198504262711 | E26: =VLOOKUP(C26,[1]在职人员信息表!$F:$G,2,FALSE) -> 人力行政中心 | F26: =VLOOKUP(C26,[1]在职人员信息表!$F:$H,3,FALSE) -> 司机 | G26: 44287 | H26: 司机限额200 | I26: 200 | M26: 司机无请示 | R26: =_xlfn.XLOOKUP(C26,'[4]20250916话费报销调整'!$B:$B,'[4]20250916话费报销调整'!$D:$D,0,0) -> 0
A27: 24 | C27: 乔宇飞 | D27: =VLOOKUP(C27,[2]在职人员信息表!$F:$U,16,FALSE) -> 15272319921015121x | E27: =VLOOKUP(C27,[1]在职人员信息表!$F:$G,2,FALSE) -> 人力行政中心 | F27: =VLOOKUP(C27,[1]在职人员信息表!$F:$H,3,FALSE) -> 司机 | G27: 44409 | H27: 司机限额200 | I27: 200 | M27: 司机无请示 | Q27: =_xlfn.XLOOKUP(C27,[3]调动人员明细表!$D:$D,[3]调动人员明细表!$F:$F,0,0) -> 44621 | R27: =_xlfn.XLOOKUP(C27,'[4]20250916话费报销调整'!$B:$B,'[4]20250916话费报销调整'!$D:$D,0,0) -> 0
A28: 25 | C28: 孙云慧 | D28: =VLOOKUP(C28,[2]在职人员信息表!$F:$U,16,FALSE) -> 152624198001010038 | E28: =VLOOKUP(C28,[1]在职人员信息表!$F:$G,2,FALSE) -> 人力行政中心 | F28: =VLOOKUP(C28,[1]在职人员信息表!$F:$H,3,FALSE) -> 司机 | G28: 45444 | H28: 司机限额200 | I28: 200 | M28: 司机无请示 | R28: =_xlfn.XLOOKUP(C28,'[4]20250916话费报销调整'!$B:$B,'[4]20250916话费报销调整'!$D:$D,0,0) -> 0
A29: 26 | C29: 董雪峰 | D29: =VLOOKUP(C29,[2]在职人员信息表!$F:$U,16,FALSE) -> 150221198911252033 | E29: =VLOOKUP(C29,[1]在职人员信息表!$F:$G,2,FALSE) -> 人力行政中心 | F29: =VLOOKUP(C29,[1]在职人员信息表!$F:$H,3,FALSE) -> 司机 | G29: 45627 | H29: 司机限额200 | I29: 200 | M29: 司机无请示 | P29: 2024年11月调动，调动后无审批 | Q29: =_xlfn.XLOOKUP(C29,[3]调动人员明细表!$D:$D,[3]调动人员明细表!$F:$F,0,0) -> 45603 | R29: =_xlfn.XLOOKUP(C29,'[4]20250916话费报销调整'!$B:$B,'[4]20250916话费报销调整'!$D:$D,0,0) -> 0
A30: 27 | C30: 刘彦飞 | D30: =VLOOKUP(C30,[2]在职人员信息表!$F:$U,16,FALSE) -> 152626198702282418 | E30: =VLOOKUP(C30,[1]在职人员信息表!$F:$G,2,FALSE) -> 人力行政中心 | F30: =VLOOKUP(C30,[1]在职人员信息表!$F:$H,3,FALSE) -> 司机 | G30: 45717 | H30: 司机限额200 | I30: 200 | M30: 司机无请示 | P30: 2025年2月调动，调动后无审批 | Q30: =_xlfn.XLOOKUP(C30,[3]调动人员明细表!$D:$D,[3]调动人员明细表!$F:$F,0,0) -> 45714 | R30: =_xlfn.XLOOKUP(C30,'[4]20250916话费报销调整'!$B:$B,'[4]20250916话费报销调整'!$D:$D,0,0) -> 0
A31: 28 | C31: 刘静平 | D31: =VLOOKUP(C31,[2]在职人员信息表!$F:$U,16,FALSE) -> 152723198301120916 | E31: =VLOOKUP(C31,[1]在职人员信息表!$F:$G,2,FALSE) -> 通风科 | F31: =VLOOKUP(C31,[1]在职人员信息表!$F:$H,3,FALSE) -> 瓦检班长 | G31: 45870 | H31: 2025年班组长评选结果公示 | I31: 200 | M31: 2025年优秀班组长 | N31: 有 | O31: 45874 | R31: =_xlfn.XLOOKUP(C31,'[4]20250916话费报销调整'!$B:$B,'[4]20250916话费报销调整'!$D:$D,0,0) -> 0 | S31: 39 | T31: 39.1 | U31: 39
A32: 29 | C32: 胡成义 | D32: =VLOOKUP(C32,[2]在职人员信息表!$F:$U,16,FALSE) -> 320322199007300832 | E32: =VLOOKUP(C32,[1]在职人员信息表!$F:$G,2,FALSE) -> 综采队 | F32: =VLOOKUP(C32,[1]在职人员信息表!$F:$H,3,FALSE) -> 班长 | G32: 45870 | I32: 200 | N32: 有 | O32: 45874 | Q32: =_xlfn.XLOOKUP(C32,[3]调动人员明细表!$D:$D,[3]调动人员明细表!$F:$F,0,0) -> 45400 | R32: =_xlfn.XLOOKUP(C32,'[4]20250916话费报销调整'!$B:$B,'[4]20250916话费报销调整'!$D:$D,0,0) -> 0 | AE32: =VLOOKUP(C32,[5]Sheet1!$C$1:$G$65536,5,FALSE) -> 江苏省沛县大屯镇丰乐村352号
A33: 30 | C33: 赵丙海 | D33: =VLOOKUP(C33,[2]在职人员信息表!$F:$U,16,FALSE) -> 210124197511263839 | E33: =VLOOKUP(C33,[1]在职人员信息表!$F:$G,2,FALSE) -> 安全监察科 | F33: =VLOOKUP(C33,[1]在职人员信息表!$F:$H,3,FALSE) -> 安检班长 | G33: 45870 | I33: 200 | N33: 有 | O33: 45874 | R33: =_xlfn.XLOOKUP(C33,'[4]20250916话费报销调整'!$B:$B,'[4]20250916话费报销调整'!$D:$D,0,0) -> 0 | S33: 108 | T33: 108 | U33: 108
A34: 31 | C34: 武军生 | D34: =VLOOKUP(C34,[2]在职人员信息表!$F:$U,16,FALSE) -> 640202198008240017 | E34: =VLOOKUP(C34,[1]在职人员信息表!$F:$G,2,FALSE) -> 机运队 | F34: =VLOOKUP(C34,[1]在职人员信息表!$F:$H,3,FALSE) -> 电工班副班长 | G34: 45870 | I34: 200 | N34: 有 | O34: 45874 | R34: =_xlfn.XLOOKUP(C34,'[4]20250916话费报销调整'!$B:$B,'[4]20250916话费报销调整'!$D:$D,0,0) -> 0 | S34: 129 | T34: 129 | U34: 129.1 | AE34: =VLOOKUP(C34,[5]Sheet1!$C$1:$G$65536,5,FALSE) -> 宁夏银川市
A35: 32 | C35: 贾海军 | D35: =VLOOKUP(C35,[2]在职人员信息表!$F:$U,16,FALSE) -> 14223419760416601X | E35: =VLOOKUP(C35,[1]在职人员信息表!$F:$G,2,FALSE) -> 复垦绿化队 | F35: =VLOOKUP(C35,[1]在职人员信息表!$F:$H,3,FALSE) -> 维修班长 | G35: 45870 | I35: 200 | N35: 有 | O35: 45874 | R35: =_xlfn.XLOOKUP(C35,'[4]20250916话费报销调整'!$B:$B,'[4]20250916话费报销调整'!$D:$D,0,0) -> 0 | S35: 109 | T35: 121.5 | U35: 109 | AE35: =VLOOKUP(C35,[5]Sheet1!$C$1:$G$65536,5,FALSE) -> 山西省偏关县
A36: 33 | C36: 高志军 | D36: =VLOOKUP(C36,[2]在职人员信息表!$F:$U,16,FALSE) -> 152801197406233311 | E36: =VLOOKUP(C36,[1]在职人员信息表!$F:$G,2,FALSE) -> 选煤厂 | F36: =VLOOKUP(C36,[1]在职人员信息表!$F:$H,3,FALSE) -> 电工班长 | G36: 45870 | I36: 200 | N36: 有 | O36: 45874 | R36: =_xlfn.XLOOKUP(C36,'[4]20250916话费报销调整'!$B:$B,'[4]20250916话费报销调整'!$D:$D,0,0) -> 0 | S36: 69 | T36: 69 | U36: 74.4 | AE36: =VLOOKUP(C36,[5]Sheet1!$C$1:$G$65536,5,FALSE) -> 内蒙古自治区巴彦淖尔市 临河区
A37: 34 | C37: 康保忠 | D37: =VLOOKUP(C37,[2]在职人员信息表!$F:$U,16,FALSE) -> 150102196809011555 | E37: =VLOOKUP(C37,[1]在职人员信息表!$F:$G,2,FALSE) -> 选煤厂 | F37: =VLOOKUP(C37,[1]在职人员信息表!$F:$H,3,FALSE) -> 快速装车班长 | G37: 45870 | I37: 200 | N37: 有 | O37: 45874 | R37: =_xlfn.XLOOKUP(C37,'[4]20250916话费报销调整'!$B:$B,'[4]20250916话费报销调整'!$D:$D,0,0) -> 0 | S37: 86.9 | T37: 86.9 | U37: 86.9 | AE37: =VLOOKUP(C37,[5]Sheet1!$C$1:$G$65536,5,FALSE) -> 内蒙古自治区呼和浩特市
A38: 35 | C38: 黄忠华 | D38: =VLOOKUP(C38,[2]在职人员信息表!$F:$U,16,FALSE) -> 150221199104104418 | E38: =VLOOKUP(C38,[1]在职人员信息表!$F:$G,2,FALSE) -> 生产机修科 | F38: =VLOOKUP(C38,[1]在职人员信息表!$F:$H,3,FALSE) -> 维修班长 | G38: 45870 | I38: 200 | N38: 有 | O38: 45874 | Q38: =_xlfn.XLOOKUP(C38,[3]调动人员明细表!$D:$D,[3]调动人员明细表!$F:$F,0,0) -> 45660 | R38: =_xlfn.XLOOKUP(C38,'[4]20250916话费报销调整'!$B:$B,'[4]20250916话费报销调整'!$D:$D,0,0) -> 0 | S38: 186.75 | T38: 147.6 | U38: 200
A39: 36 | C39: 李安喜 | E39: 机运队 | F39: =VLOOKUP(C39,[1]在职人员信息表!$F:$H,3,FALSE) -> 地面电工 | I39: 200
A40: 37 | C40: 杨纪仓 | E40: 综采队 | F40: =VLOOKUP(C40,[1]在职人员信息表!$F:$H,3,FALSE) -> 检修班班长 | I40: 200
...

Sheet Sheet1
A1: 内蒙古准格尔旗力量煤业有限公司人员2025年员工福利档案
A2: 序号 | B2: 姓名 | C2: 工作部门 | D2: 岗位 | E2: 级别 | F2: 任职日期 | G2: 话费报销标准 | H2: 燃油标准 | I2: 电话费 | W2: 探亲地 | X2: 第一次探亲 | AA2: 第二次探亲 | AD2: 第三次探亲 | AG2: 第四次探亲 | AJ2: 第五次探亲 | AM2: 第六次探亲 | AP2: 探亲费 总金额 | AQ2: 报销合计 金额 | AR2: 备案日期 | AS2: 经办人 | AT2: 备注
I3: 1月 | J3: 2月 | K3: 3月 | L3: 4月 | M3: 5月 | N3: 6月 | O3: 7月 | P3: 8月 | Q3: 9月 | R3: 10月 | S3: 11月 | T3: 12月 | U3: 13月 | V3: 14月 | X3: 开始时间 | Y3: 结束时间 | Z3: 金额 | AA3: 开始时间 | AB3: 结束时间 | AC3: 金额 | AD3: 开始时间 | AE3: 结束时间 | AF3: 金额 | AG3: 开始时间 | AH3: 结束时间 | AI3: 金额 | AJ3: 开始时间 | AK3: 结束时间 | AL3: 金额 | AM3: 开始时间 | AN3: 结束时间 | AO3: 金额
A4: 1 | B4: 李波 | C4: =VLOOKUP(B4,[2]在职人员信息表!$F:$G,2,FALSE) -> 公司领导 | D4: =VLOOKUP(B4,[2]在职人员信息表!$F:$H,3,FALSE) -> 董事长 | E4: 董事长 | F4: =VLOOKUP(B4,[2]任职汇总表!$D:$I,6,FALSE()) -> 45235
A5: 2 | B5: 章杨 | C5: =VLOOKUP(B5,[2]在职人员信息表!$F:$G,2,FALSE) -> 公司领导 | D5: =VLOOKUP(B5,[2]在职人员信息表!$F:$H,3,FALSE) -> 总经理 | E5: 总经理级 | F5: =VLOOKUP(B5,[2]任职汇总表!$D:$I,6,FALSE()) -> 45486 | I5: 792.12 | J5: 800 | K5: 542.2 | L5: 542.4 | M5: 543.1 | N5: 555.4 | O5: 560.5 | X5: 45703 | Y5: 45705 | Z5: 485 | AA5: 45727 | AB5: 45730 | AC5: 406 | AD5: 45750 | AE5: 45753 | AF5: 430 | AG5: 45777 | AH5: 45785 | AI5: 533
A6: 3 | B6: 奚明 | C6: =VLOOKUP(B6,[2]在职人员信息表!$F:$G,2,FALSE) -> 公司领导 | D6: =VLOOKUP(B6,[2]在职人员信息表!$F:$H,3,FALSE) -> 常务副总经理 | E6: 副总级 | F6: =VLOOKUP(B6,[2]任职汇总表!$D:$I,6,FALSE()) -> 44880 | I6: 248 | J6: 248.1 | K6: 248.1 | L6: 248 | M6: 248 | N6: 248
A7: 4 | B7: 窦发权 | C7: =VLOOKUP(B7,[2]在职人员信息表!$F:$G,2,FALSE) -> 公司领导 | D7: =VLOOKUP(B7,[2]在职人员信息表!$F:$H,3,FALSE) -> 总工程师 | E7: 总经理级 | F7: =VLOOKUP(B7,[2]任职汇总表!$D:$I,6,FALSE()) -> 45181 | I7: 131.78 | J7: 139.5 | K7: 144.5 | L7: 244.2 | M7: 454 | N7: 144.2 | W7: 山东泰安 | X7: 45805 | Y7: 45813 | Z7: 1246.47
A8: 5 | B8: 宋云飞 | C8: =VLOOKUP(B8,[2]在职人员信息表!$F:$G,2,FALSE) -> 公司领导 | D8: =VLOOKUP(B8,[2]在职人员信息表!$F:$H,3,FALSE) -> 副总经理 | E8: 副总级 | F8: =VLOOKUP(B8,[2]任职汇总表!$D:$I,6,FALSE()) -> 45555 | I8: 289.9 | J8: 310.9 | K8: 281 | W8: =VLOOKUP(B8,Sheet1!$B$4:$B$95,5,FALSE) -> #REF!
A9: 6 | B9: 周洪刚 | C9: =VLOOKUP(B9,[2]在职人员信息表!$F:$G,2,FALSE) -> 公司领导 | D9: =VLOOKUP(B9,[2]在职人员信息表!$F:$H,3,FALSE) -> 总经理助理兼多种经营部经理 | E9: 副总级 | F9: =VLOOKUP(B9,[2]任职汇总表!$D:$I,6,FALSE()) -> 43164 | H9: 1000 | I9: 138.7 | J9: 138.7 | K9: 138 | W9: =VLOOKUP(B9,Sheet1!$B$4:$B$95,5,FALSE) -> #REF! | X9: 45682 | Y9: 45692 | Z9: 1226.89 | AA9: 45743 | AB9: 45753 | AC9: 1146.81 | AD9: 45773 | AE9: 45799 | AF9: 677
A10: 7 | B10: 王震 | C10: =VLOOKUP(B10,[2]在职人员信息表!$F:$G,2,FALSE) -> 公司领导 | D10: =VLOOKUP(B10,[2]在职人员信息表!$F:$H,3,FALSE) -> 副总经理 | E10: 副总级 | F10: =VLOOKUP(B10,[2]任职汇总表!$D:$I,6,FALSE()) -> 44917 | H10: 1000 | I10: 306.7 | J10: 306.51 | K10: 309.2 | L10: 297.2 | M10: 305.8 | N10: 295.9
A11: 8 | B11: 李秦生 | C11: =VLOOKUP(B11,[2]在职人员信息表!$F:$G,2,FALSE) -> 公司领导 | D11: =VLOOKUP(B11,[2]在职人员信息表!$F:$H,3,FALSE) -> 副总经理兼矿长 | E11: 副总级 | F11: =VLOOKUP(B11,[2]任职汇总表!$D:$I,6,FALSE()) -> 45486 | I11: 386.3 | J11: 386.2 | K11: 387.2 | L11: 386.8 | M11: 386.2 | N11: 386.7 | W11: =VLOOKUP(B11,Sheet1!$B$4:$B$95,5,FALSE) -> #REF! | X11: 45684 | Y11: 45692 | Z11: 2599 | AA11: 45680 | AB11: 45702 | AC11: 2967.33 | AD11: 45680 | AE11: 45702 | AF11: 1656.67
A12: 9 | B12: 赵佳 | C12: =VLOOKUP(B12,[2]在职人员信息表!$F:$G,2,FALSE) -> 公司领导 | D12: =VLOOKUP(B12,[2]在职人员信息表!$F:$H,3,FALSE) -> 力量发展财务副总监兼力量煤业财务总监 | E12: 副总级 | F12: =VLOOKUP(B12,[2]任职汇总表!$D:$I,6,FALSE()) -> 45861
A13: 10 | B13: 杨维海 | C13: =VLOOKUP(B13,[2]在职人员信息表!$F:$G,2,FALSE) -> 矿级领导 | D13: =VLOOKUP(B13,[2]在职人员信息表!$F:$H,3,FALSE) -> 副矿长 | E13: 高级经理级 | F13: =VLOOKUP(B13,[2]任职汇总表!$D:$I,6,FALSE()) -> 45642 | I13: 178.4 | J13: 178.5 | K13: 218.4 | L13: 188.4 | M13: 148.8 | N13: 148.4 | W13: =VLOOKUP(B13,Sheet1!$B$4:$B$95,5,FALSE) -> #REF! | X13: 45787 | Y13: 45797 | Z13: 2246.56
A14: 11 | B14: 高翔 | C14: =VLOOKUP(B14,[2]在职人员信息表!$F:$G,2,FALSE) -> 矿级领导 | D14: =VLOOKUP(B14,[2]在职人员信息表!$F:$H,3,FALSE) -> 生产副矿长 | E14: 高级经理级 | F14: =VLOOKUP(B14,[2]任职汇总表!$D:$I,6,FALSE()) -> 45642 | I14: 280 | J14: 280 | K14: 270 | W14: =VLOOKUP(B14,Sheet1!$B$4:$B$95,5,FALSE) -> #REF! | X14: 45658 | Y14: 45668 | Z14: 1024.99 | AA14: 45699 | AB14: 45708 | AC14: 1052.52 | AD14: 45814 | AE14: 45825 | AF14: 549.35
A15: 12 | B15: 王荣 | C15: =VLOOKUP(B15,[2]在职人员信息表!$F:$G,2,FALSE) -> 矿级领导 | D15: =VLOOKUP(B15,[2]在职人员信息表!$F:$H,3,FALSE) -> 总工程师 | E15: 高级经理级 | F15: =VLOOKUP(B15,[2]任职汇总表!$D:$I,6,FALSE()) -> 45642 | I15: 450.1 | J15: 480.3 | K15: 600 | L15: 485 | M15: 600 | N15: 582.24 | W15: =VLOOKUP(B15,Sheet1!$B$4:$B$95,5,FALSE) -> #REF! | X15: 45684 | Y15: 45692 | Z15: 1516.83 | AA15: 45801 | AB15: 45811 | AC15: 1346.66
A16: 13 | B16: 陈永清 | C16: =VLOOKUP(B16,[2]在职人员信息表!$F:$G,2,FALSE) -> 矿级领导 | D16: =VLOOKUP(B16,[2]在职人员信息表!$F:$H,3,FALSE) -> 机电副矿长 | E16: 高级经理级 | F16: =VLOOKUP(B16,[2]任职汇总表!$D:$I,6,FALSE()) -> 45642 | I16: 100 | J16: 100 | K16: 100 | W16: =VLOOKUP(B16,Sheet1!$B$4:$B$95,5,FALSE) -> #REF! | X16: 45658 | Y16: 45668 | Z16: 1296 | AA16: 45697 | AB16: 45707 | AC16: 1270 | AD16: 45794 | AE16: 45804 | AF16: 1403.5
A17: 14 | B17: 谈安彬 | C17: =VLOOKUP(B17,[2]在职人员信息表!$F:$G,2,FALSE) -> 矿级领导 | D17: =VLOOKUP(B17,[2]在职人员信息表!$F:$H,3,FALSE) -> 地质防治水副总工程师 | E17: 正经理级/副矿级 | F17: =VLOOKUP(B17,[2]任职汇总表!$D:$I,6,FALSE()) -> 45460 | I17: 169.6 | J17: 169.9 | K17: 169.2 | L17: 169.4 | M17: 169.2 | N17: 169.1 | W17: =VLOOKUP(B17,Sheet1!$B$4:$B$95,5,FALSE) -> #REF! | X17: 45684 | Y17: 45692 | Z17: 1356.05 | AA17: 45815 | AB17: 45825 | AC17: 1374.05
A18: 15 | B18: 李亚杰 | C18: =VLOOKUP(B18,[2]在职人员信息表!$F:$G,2,FALSE) -> 矿级领导 | D18: =VLOOKUP(B18,[2]在职人员信息表!$F:$H,3,FALSE) -> 安全副总工程师 | E18: 正经理级/副矿级 | F18: =VLOOKUP(B18,[2]任职汇总表!$D:$I,6,FALSE()) -> 45423 | I18: 234.51 | J18: 234.71 | K18: 234.61 | L18: 259.01 | M18: 347.11 | N18: 259.11 | W18: =VLOOKUP(B18,Sheet1!$B$4:$B$95,5,FALSE) -> #REF! | X18: 45766 | Y18: 45776 | Z18: 1383.16
A19: 16 | B19: 付浩声 | C19: =VLOOKUP(B19,[2]在职人员信息表!$F:$G,2,FALSE) -> 矿级领导 | D19: =VLOOKUP(B19,[2]在职人员信息表!$F:$H,3,FALSE) -> 机电副总工程师 | E19: 正经理级/副矿级 | F19: =VLOOKUP(B19,[2]任职汇总表!$D:$I,6,FALSE()) -> 45423 | I19: 180.2 | J19: 180 | K19: 180.2 | W19: =VLOOKUP(B19,Sheet1!$B$4:$B$95,5,FALSE) -> #REF! | X19: 45682 | Y19: 45690 | Z19: 1239 | AA19: 45837 | AB19: 45847 | AC19: 1328.88
A20: 17 | B20: 张春宝 | C20: =VLOOKUP(B20,[2]在职人员信息表!$F:$G,2,FALSE) -> 通风科 | D20: =VLOOKUP(B20,[2]在职人员信息表!$F:$H,3,FALSE) -> 通风副总工程师 | E20: 正经理级/副矿级 | F20: =VLOOKUP(B20,[2]任职汇总表!$D:$I,6,FALSE()) -> 45597 | I20: 381.6 | J20: 374.08 | K20: 347.75 | L20: 307.9 | M20: 306.28 | N20: 295.61 | W20: =VLOOKUP(B20,Sheet1!$B$4:$B$95,5,FALSE) -> #REF! | X20: 45807 | Y20: 45817 | Z20: 1730
A21: 18 | B21: 孙启明 | C21: =VLOOKUP(B21,[2]在职人员信息表!$F:$G,2,FALSE) -> 综采队 | D21: =VLOOKUP(B21,[2]在职人员信息表!$F:$H,3,FALSE) -> 矿长助理兼综采队队长 | E21: 正经理级/副矿级 | F21: =VLOOKUP(B21,[2]任职汇总表!$D:$I,6,FALSE()) -> 45597 | I21: 180.5 | J21: 282.65 | K21: 307.8 | W21: =VLOOKUP(B21,Sheet1!$B$4:$B$95,5,FALSE) -> #REF! | X21: 45668 | Y21: 45669 | Z21: 274.5 | AA21: 45739 | AB21: 45739 | AC21: 280
A22: 19 | B22: 张广振 | C22: =VLOOKUP(B22,[2]在职人员信息表!$F:$G,2,FALSE) -> 综采队 | D22: =VLOOKUP(B22,[2]在职人员信息表!$F:$H,3,FALSE) -> 常务副队长 | E22: 副经理级/正科级 | F22: =VLOOKUP(B22,[2]任职汇总表!$D:$I,6,FALSE()) -> 45090 | I22: 131 | J22: 131.4 | K22: 131.4 | W22: =VLOOKUP(B22,Sheet1!$B$4:$B$95,5,FALSE) -> #REF! | X22: 45722 | Y22: 45727 | Z22: 1124 | AA22: 45755 | AB22: 45760 | AC22: 1093
A23: 20 | B23: 杨培 | C23: =VLOOKUP(B23,[2]在职人员信息表!$F:$G,2,FALSE) -> 综采队 | D23: =VLOOKUP(B23,[2]在职人员信息表!$F:$H,3,FALSE) -> 副队长 | E23: 副科级/经理助理/主管 | F23: =VLOOKUP(B23,[2]任职汇总表!$D:$I,6,FALSE()) -> 44958 | I23: 182.4 | J23: 182.1 | K23: 182
A24: 21 | B24: 商好学 | C24: =VLOOKUP(B24,[2]在职人员信息表!$F:$G,2,FALSE) -> 综采队 | D24: =VLOOKUP(B24,[2]在职人员信息表!$F:$H,3,FALSE) -> 副队长 | E24: 副科级/经理助理/主管 | F24: =VLOOKUP(B24,[2]任职汇总表!$D:$I,6,FALSE()) -> 44958 | I24: 145 | J24: 149 | K24: 149.2 | W24: =VLOOKUP(B24,Sheet1!$B$4:$B$95,5,FALSE) -> #REF! | X24: 45742 | Y24: 45751 | Z24: 500
A25: 22 | B25: 杨肖 | C25: =VLOOKUP(B25,[2]在职人员信息表!$F:$G,2,FALSE) -> 综采队 | D25: =VLOOKUP(B25,[2]在职人员信息表!$F:$H,3,FALSE) -> 综采安装材料主管 | E25: 副科级/经理助理/主管 | F25: =VLOOKUP(B25,[2]任职汇总表!$D:$I,6,FALSE()) -> #N/A | I25: 161.8 | J25: 170 | K25: 145.05 | W25: =VLOOKUP(B25,Sheet1!$B$4:$B$95,5,FALSE) -> #REF! | X25: 2025-3.26 | Y25: 45752 | Z25: 1000
A26: 23 | B26: 尹树山 | C26: =VLOOKUP(B26,[2]在职人员信息表!$F:$G,2,FALSE) -> 综采队 | D26: =VLOOKUP(B26,[2]在职人员信息表!$F:$H,3,FALSE) -> 副队长 | E26: 副科级/经理助理/主管 | F26: =VLOOKUP(B26,[2]任职汇总表!$D:$I,6,FALSE()) -> 44958 | I26: 169 | J26: 169 | K26: 169 | W26: =VLOOKUP(B26,Sheet1!$B$4:$B$95,5,FALSE) -> #REF! | X26: 45714 | Y26: 45722 | Z26: 474.5 | AA26: 45773 | AB26: 45777 | AC26: 521.5
A27: 24 | B27: 张坤 | C27: =VLOOKUP(B27,[2]在职人员信息表!$F:$G,2,FALSE) -> 综采队 | D27: =VLOOKUP(B27,[2]在职人员信息表!$F:$H,3,FALSE) -> 副队长 | E27: 副科级/经理助理/主管 | F27: =VLOOKUP(B27,[2]任职汇总表!$D:$I,6,FALSE()) -> 44958 | I27: 130.9 | J27: 130.9 | K27: 130.9 | W27: =VLOOKUP(B27,Sheet1!$B$4:$B$95,5,FALSE) -> #REF!
A28: 25 | B28: 索爱军 | C28: =VLOOKUP(B28,[2]在职人员信息表!$F:$G,2,FALSE) -> 综掘队 | D28: =VLOOKUP(B28,[2]在职人员信息表!$F:$H,3,FALSE) -> 副队长 | E28: 副科级/经理助理/主管 | F28: =VLOOKUP(B28,[2]任职汇总表!$D:$I,6,FALSE()) -> 44964 | I28: 200 | J28: 200 | K28: 200 | L28: 200 | M28: 200 | N28: 200 | W28: =VLOOKUP(B28,Sheet1!$B$4:$B$95,5,FALSE) -> #REF! | X28: 45684 | Y28: 45692 | Z28: 1000 | AA28: 45764 | AB28: 45774 | AC28: 1000
A29: 26 | B29: 荣启亭 | C29: =VLOOKUP(B29,[2]在职人员信息表!$F:$G,2,FALSE) -> 综掘队 | D29: =VLOOKUP(B29,[2]在职人员信息表!$F:$H,3,FALSE) -> 队长 | E29: 副经理级/ 正科级 | F29: =VLOOKUP(B29,[2]任职汇总表!$D:$I,6,FALSE()) -> 45866 | I29: 114.25 | J29: 136.3 | K29: 158.35 | L29: 132.55 | M29: 125.05 | N29: 174.85 | W29: =VLOOKUP(B29,Sheet1!$B$4:$B$95,5,FALSE) -> #REF!
A30: 27 | B30: 刘凤山 | C30: =VLOOKUP(B30,[2]在职人员信息表!$F:$G,2,FALSE) -> 综掘队 | D30: =VLOOKUP(B30,[2]在职人员信息表!$F:$H,3,FALSE) -> 副队长 | E30: 副科级/经理助理/主管 | F30: =VLOOKUP(B30,[2]任职汇总表!$D:$I,6,FALSE()) -> 44964 | I30: 169.4 | J30: 168.7 | K30: 168 | L30: 168.7 | M30: 168.2 | N30: 168 | W30: =VLOOKUP(B30,Sheet1!$B$4:$B$95,5,FALSE) -> #REF! | X30: 45770 | Y30: 45780 | Z30: 1000
A31: 28 | B31: 索爱国 | C31: =VLOOKUP(B31,[2]在职人员信息表!$F:$G,2,FALSE) -> 综掘队 | D31: =VLOOKUP(B31,[2]在职人员信息表!$F:$H,3,FALSE) -> 副队长 | E31: 副科级/经理助理/主管 | F31: =VLOOKUP(B31,[2]任职汇总表!$D:$I,6,FALSE()) -> 45881
A32: 29 | B32: 贺伟 | C32: =VLOOKUP(B32,[2]在职人员信息表!$F:$G,2,FALSE) -> 安全监察科 | D32: =VLOOKUP(B32,[2]在职人员信息表!$F:$H,3,FALSE) -> 科长 | E32: 副经理级/正科级 | F32: =VLOOKUP(B32,[2]任职汇总表!$D:$I,6,FALSE()) -> 45145 | I32: 151 | J32: 131.9 | K32: 132.2 | L32: 131.3 | M32: 131.5 | N32: 141.2
A33: 30 | B33: 郭小强 | C33: =VLOOKUP(B33,[2]在职人员信息表!$F:$G,2,FALSE) -> 安全监察科 | D33: =VLOOKUP(B33,[2]在职人员信息表!$F:$H,3,FALSE) -> 副科长 | E33: 副科级/经理助理/主管 | F33: =VLOOKUP(B33,[2]任职汇总表!$D:$I,6,FALSE()) -> 44607 | I33: 179 | J33: 179.9 | K33: 179.3 | L33: 179 | M33: 179.1 | N33: 177.76 | W33: =VLOOKUP(B33,Sheet1!$B$4:$B$95,5,FALSE) -> #REF! | X33: 45708 | Y33: 45711 | Z33: 717.39 | AA33: 45792 | AB33: 45795 | AC33: 732.74 | AD33: 2025.6.27 | AE33: 45838 | AF33: 733.91
A34: 31 | B34: 尹烈欢 | C34: =VLOOKUP(B34,[2]在职人员信息表!$F:$G,2,FALSE) -> 机运队 | D34: =VLOOKUP(B34,[2]在职人员信息表!$F:$H,3,FALSE) -> 矿长助理兼机运队队长 | E34: 正经理级/副矿级 | F34: =VLOOKUP(B34,[2]任职汇总表!$D:$I,6,FALSE()) -> 45698 | I34: 322.7 | J34: 322.8 | K34: 322.5 | L34: 322.4 | M34: 322.7 | N34: 322.4 | W34: =VLOOKUP(B34,Sheet1!$B$4:$B$95,5,FALSE) -> #REF! | X34: 45684 | Y34: 45692 | Z34: 2000
A35: 32 | B35: 程学军 | C35: =VLOOKUP(B35,[2]在职人员信息表!$F:$G,2,FALSE) -> 机运队 | D35: =VLOOKUP(B35,[2]在职人员信息表!$F:$H,3,FALSE) -> 副队长 | E35: 副科级/经理助理/主管 | F35: =VLOOKUP(B35,[2]任职汇总表!$D:$I,6,FALSE()) -> 41432 | I35: 186.1 | J35: 196.52 | K35: 185.9 | L35: 200 | M35: 200 | N35: 200 | W35: =VLOOKUP(B35,Sheet1!$B$4:$B$95,5,FALSE) -> #REF! | X35: 45763 | Y35: 45773 | Z35: 560
A36: 33 | B36: 李龙博 | C36: =VLOOKUP(B36,[2]在职人员信息表!$F:$G,2,FALSE) -> 机运队 | D36: =VLOOKUP(B36,[2]在职人员信息表!$F:$H,3,FALSE) -> 副队长 | E36: 副科级/经理助理/主管 | F36: =VLOOKUP(B36,[2]任职汇总表!$D:$I,6,FALSE()) -> 44653 | I36: 68 | J36: 68 | K36: 68 | L36: 68 | M36: 68 | N36: 68 | W36: =VLOOKUP(B36,Sheet1!$B$4:$B$95,5,FALSE) -> #REF! | X36: 45710 | Y36: 45716 | Z36: 1000
A37: 34 | B37: 孙珠红 | C37: =VLOOKUP(B37,[2]在职人员信息表!$F:$G,2,FALSE) -> 机运队 | D37: =VLOOKUP(B37,[2]在职人员信息表!$F:$H,3,FALSE) -> 检修班班长 | E37: 副科级/经理助理/主管 | F37: =VLOOKUP(B37,[2]任职汇总表!$D:$I,6,FALSE()) -> 45012 | I37: 114.87 | J37: 146 | K37: 146 | L37: 146 | M37: 200 | N37: 59.5 | W37: =VLOOKUP(B37,Sheet1!$B$4:$B$95,5,FALSE) -> #REF!
A38: 35 | B38: 史红军 | C38: =VLOOKUP(B38,[2]在职人员信息表!$F:$G,2,FALSE) -> 选煤厂 | D38: =VLOOKUP(B38,[2]在职人员信息表!$F:$H,3,FALSE) -> 总经理助理兼选煤厂厂长 | E38: 高级经理级 | F38: =VLOOKUP(B38,[2]任职汇总表!$D:$I,6,FALSE()) -> 45286 | I38: 219 | J38: 162.1 | K38: 162.6 | L38: 162.1 | M38: 162.1 | N38: 162.1 | W38: =VLOOKUP(B38,Sheet1!$B$4:$B$95,5,FALSE) -> #REF! | X38: 45694 | Y38: 45698 | Z38: 2540.37 | AA38: 45759 | AB38: 45767 | AC38: 2533.07 | AD38: 45872 | AE38: 45882 | AF38: 2639.42
A39: 36 | B39: 王亮勋 | C39: =VLOOKUP(B39,[2]在职人员信息表!$F:$G,2,FALSE) -> 选煤厂 | D39: =VLOOKUP(B39,[2]在职人员信息表!$F:$H,3,FALSE) -> 安全副厂长 | E39: 副经理级/正科级 | F39: =VLOOKUP(B39,[2]任职汇总表!$D:$I,6,FALSE()) -> 44210 | I39: 199.5 | J39: 199 | K39: 199 | L39: 199 | M39: 210.25 | N39: 219
A40: 37 | B40: 张磊 | C40: =VLOOKUP(B40,[2]在职人员信息表!$F:$G,2,FALSE) -> 选煤厂 | D40: =VLOOKUP(B40,[2]在职人员信息表!$F:$H,3,FALSE) -> 常务副厂长 | E40: 正经理级/副矿级 | F40: =VLOOKUP(B40,[2]任职汇总表!$D:$I,6,FALSE()) -> 45775 | I40: 180.1 | J40: 180.1 | K40: 180.1 | L40: 180.3 | M40: 180.6 | N40: 180
...

Sheet 任命人员话费福利
A1: 2025年内蒙古准格尔旗力量煤业有限公司主管（含）以上人员 话费及燃油费报销台账
A2: 序号 | C2: 姓名 | D2: 身份证号 | E2: 工作部门 | F2: 岗位 | G2: 话费报销情况 | J2: 燃油报销情况 （元/月） | K2: 备注
C3: 姓名 | D3: 身份证号 | E3: 工作部门 | F3: 岗位 | G3: 级别 | H3: 话费开始报销月份 | I3: 话费报销标准（元/月）
A4: 1 | C4: 李波 | D4: =VLOOKUP(C4,[2]在职人员信息表!$F:$U,16,FALSE) -> 130522198205272415 | E4: =VLOOKUP(C4,[2]在职人员信息表!$F:$G,2,FALSE) -> 公司领导 | F4: =VLOOKUP(C4,[2]在职人员信息表!$F:$H,3,FALSE) -> 董事长 | G4: 董事长 | H4: =VLOOKUP(C4,[2]任职汇总表!$D:$I,6,FALSE()) -> 45235 | I4: 800
A5: 2 | C5: 章杨 | D5: =VLOOKUP(C5,[2]在职人员信息表!$F:$U,16,FALSE) -> 42030019810508031X | E5: =VLOOKUP(C5,[2]在职人员信息表!$F:$G,2,FALSE) -> 公司领导 | F5: =VLOOKUP(C5,[2]在职人员信息表!$F:$H,3,FALSE) -> 总经理 | G5: 总经理级 | H5: =VLOOKUP(C5,[2]任职汇总表!$D:$I,6,FALSE()) -> 45486 | I5: 800
A6: 3 | C6: 窦发权 | D6: =VLOOKUP(C6,[2]在职人员信息表!$F:$U,16,FALSE) -> 370902197109021292 | E6: =VLOOKUP(C6,[2]在职人员信息表!$F:$G,2,FALSE) -> 公司领导 | F6: =VLOOKUP(C6,[2]在职人员信息表!$F:$H,3,FALSE) -> 总工程师 | G6: 总经理级 | H6: =VLOOKUP(C6,[2]任职汇总表!$D:$I,6,FALSE()) -> 45181 | I6: 800
A7: 4 | C7: 奚明 | D7: =VLOOKUP(C7,[2]在职人员信息表!$F:$U,16,FALSE) -> 21128219830626081X | E7: =VLOOKUP(C7,[2]在职人员信息表!$F:$G,2,FALSE) -> 公司领导 | F7: =VLOOKUP(C7,[2]在职人员信息表!$F:$H,3,FALSE) -> 常务副总经理 | G7: 副总级 | H7: =VLOOKUP(C7,[2]任职汇总表!$D:$I,6,FALSE()) -> 44880 | I7: 600
A8: 5 | C8: 宋云飞 | D8: =VLOOKUP(C8,[2]在职人员信息表!$F:$U,16,FALSE) -> 230822198111094910 | E8: =VLOOKUP(C8,[2]在职人员信息表!$F:$G,2,FALSE) -> 公司领导 | F8: =VLOOKUP(C8,[2]在职人员信息表!$F:$H,3,FALSE) -> 副总经理 | G8: 副总级 | H8: =VLOOKUP(C8,[2]任职汇总表!$D:$I,6,FALSE()) -> 45555 | I8: 600
A9: 6 | C9: 周洪刚 | D9: =VLOOKUP(C9,[2]在职人员信息表!$F:$U,16,FALSE) -> 130403196411292114 | E9: =VLOOKUP(C9,[2]在职人员信息表!$F:$G,2,FALSE) -> 公司领导 | F9: =VLOOKUP(C9,[2]在职人员信息表!$F:$H,3,FALSE) -> 总经理助理兼多种经营部经理 | G9: 副总级 | H9: =VLOOKUP(C9,[2]任职汇总表!$D:$I,6,FALSE()) -> 43164 | I9: 600 | J9: 1000
A10: 7 | C10: 王震 | D10: =VLOOKUP(C10,[2]在职人员信息表!$F:$U,16,FALSE) -> 152723198509184812 | E10: =VLOOKUP(C10,[2]在职人员信息表!$F:$G,2,FALSE) -> 公司领导 | F10: =VLOOKUP(C10,[2]在职人员信息表!$F:$H,3,FALSE) -> 副总经理 | G10: 副总级 | H10: =VLOOKUP(C10,[2]任职汇总表!$D:$I,6,FALSE()) -> 44917 | I10: 600 | J10: 1000
A11: 8 | C11: 李秦生 | D11: =VLOOKUP(C11,[2]在职人员信息表!$F:$U,16,FALSE) -> 362329198611264574 | E11: =VLOOKUP(C11,[2]在职人员信息表!$F:$G,2,FALSE) -> 公司领导 | F11: =VLOOKUP(C11,[2]在职人员信息表!$F:$H,3,FALSE) -> 副总经理兼矿长 | G11: 副总级 | H11: =VLOOKUP(C11,[2]任职汇总表!$D:$I,6,FALSE()) -> 45486 | I11: 600
A12: 9 | C12: 赵佳 | D12: =VLOOKUP(C12,[2]在职人员信息表!$F:$U,16,FALSE) -> 150122198401160527 | E12: =VLOOKUP(C12,[2]在职人员信息表!$F:$G,2,FALSE) -> 公司领导 | F12: =VLOOKUP(C12,[2]在职人员信息表!$F:$H,3,FALSE) -> 力量发展财务副总监兼力量煤业财务总监 | G12: 副总级 | H12: =VLOOKUP(C12,[2]任职汇总表!$D:$I,6,FALSE()) -> 45861 | I12: 600
A13: 10 | C13: 杨维海 | D13: =VLOOKUP(C13,[2]在职人员信息表!$F:$U,16,FALSE) -> 340403197510102439 | E13: =VLOOKUP(C13,[2]在职人员信息表!$F:$G,2,FALSE) -> 矿级领导 | F13: =VLOOKUP(C13,[2]在职人员信息表!$F:$H,3,FALSE) -> 副矿长 | G13: 高级经理级 | H13: =VLOOKUP(C13,[2]任职汇总表!$D:$I,6,FALSE()) -> 45642 | I13: 600
A14: 11 | C14: 高翔 | D14: =VLOOKUP(C14,[2]在职人员信息表!$F:$U,16,FALSE) -> 14010219810504601X | E14: =VLOOKUP(C14,[2]在职人员信息表!$F:$G,2,FALSE) -> 矿级领导 | F14: =VLOOKUP(C14,[2]在职人员信息表!$F:$H,3,FALSE) -> 生产副矿长 | G14: 高级经理级 | H14: =VLOOKUP(C14,[2]任职汇总表!$D:$I,6,FALSE()) -> 45642 | I14: 600
A15: 12 | C15: 王荣 | D15: =VLOOKUP(C15,[2]在职人员信息表!$F:$U,16,FALSE) -> 140581198801043215 | E15: =VLOOKUP(C15,[2]在职人员信息表!$F:$G,2,FALSE) -> 矿级领导 | F15: =VLOOKUP(C15,[2]在职人员信息表!$F:$H,3,FALSE) -> 总工程师 | G15: 高级经理级 | H15: =VLOOKUP(C15,[2]任职汇总表!$D:$I,6,FALSE()) -> 45642 | I15: 600
A16: 13 | C16: 陈永清 | D16: =VLOOKUP(C16,[2]在职人员信息表!$F:$U,16,FALSE) -> 230321197809105011 | E16: =VLOOKUP(C16,[2]在职人员信息表!$F:$G,2,FALSE) -> 矿级领导 | F16: =VLOOKUP(C16,[2]在职人员信息表!$F:$H,3,FALSE) -> 机电副矿长 | G16: 高级经理级 | H16: =VLOOKUP(C16,[2]任职汇总表!$D:$I,6,FALSE()) -> 45642 | I16: 600
A17: 14 | C17: 史红军 | D17: =VLOOKUP(C17,[2]在职人员信息表!$F:$U,16,FALSE) -> 412328197409081532 | E17: =VLOOKUP(C17,[2]在职人员信息表!$F:$G,2,FALSE) -> 选煤厂 | F17: =VLOOKUP(C17,[2]在职人员信息表!$F:$H,3,FALSE) -> 总经理助理兼选煤厂厂长 | G17: 高级经理级 | H17: =VLOOKUP(C17,[2]任职汇总表!$D:$I,6,FALSE()) -> 45286 | I17: 600
A18: 15 | C18: 谈安彬 | D18: =VLOOKUP(C18,[2]在职人员信息表!$F:$U,16,FALSE) -> 512323198105240334 | E18: =VLOOKUP(C18,[2]在职人员信息表!$F:$G,2,FALSE) -> 矿级领导 | F18: =VLOOKUP(C18,[2]在职人员信息表!$F:$H,3,FALSE) -> 地质防治水副总工程师 | G18: 正经理级/副矿级 | H18: =VLOOKUP(C18,[2]任职汇总表!$D:$I,6,FALSE()) -> 45460 | I18: 400
A19: 16 | C19: 李亚杰 | D19: =VLOOKUP(C19,[2]在职人员信息表!$F:$U,16,FALSE) -> 140428198808152812 | E19: =VLOOKUP(C19,[2]在职人员信息表!$F:$G,2,FALSE) -> 矿级领导 | F19: =VLOOKUP(C19,[2]在职人员信息表!$F:$H,3,FALSE) -> 安全副总工程师 | G19: 正经理级/副矿级 | H19: =VLOOKUP(C19,[2]任职汇总表!$D:$I,6,FALSE()) -> 45423 | I19: 400
A20: 17 | C20: 付浩声 | D20: =VLOOKUP(C20,[2]在职人员信息表!$F:$U,16,FALSE) -> 370983198605021358 | E20: =VLOOKUP(C20,[2]在职人员信息表!$F:$G,2,FALSE) -> 矿级领导 | F20: =VLOOKUP(C20,[2]在职人员信息表!$F:$H,3,FALSE) -> 机电副总工程师 | G20: 正经理级/副矿级 | H20: =VLOOKUP(C20,[2]任职汇总表!$D:$I,6,FALSE()) -> 45423 | I20: 400
A21: 18 | C21: 张春宝 | D21: =VLOOKUP(C21,[2]在职人员信息表!$F:$U,16,FALSE) -> 152103198304015478 | E21: =VLOOKUP(C21,[2]在职人员信息表!$F:$G,2,FALSE) -> 通风科 | F21: =VLOOKUP(C21,[2]在职人员信息表!$F:$H,3,FALSE) -> 通风副总工程师 | G21: 正经理级/副矿级 | H21: =VLOOKUP(C21,[2]任职汇总表!$D:$I,6,FALSE()) -> 45597 | I21: 400
A22: 19 | C22: 孙启明 | D22: =VLOOKUP(C22,[2]在职人员信息表!$F:$U,16,FALSE) -> 150428198903200159 | E22: =VLOOKUP(C22,[2]在职人员信息表!$F:$G,2,FALSE) -> 综采队 | F22: =VLOOKUP(C22,[2]在职人员信息表!$F:$H,3,FALSE) -> 矿长助理兼综采队队长 | G22: 正经理级/副矿级 | H22: =VLOOKUP(C22,[2]任职汇总表!$D:$I,6,FALSE()) -> 45597 | I22: 400
... A24: 21 | C24: 张磊 | D24: =VLOOKUP(C24,[2]在职人员信息表!$F:$U,16,FALSE) -> 140108198805043918 | E24: =VLOOKUP(C24,[2]在职人员信息表!$F:$G,2,FALSE) -> 选煤厂 | F24: =VLOOKUP(C24,[2]在职人员信息表!$F:$H,3,FALSE) -> 常务副厂长 | G24: 正经理级/副矿级 | H24: =VLOOKUP(C24,[2]任职汇总表!$D:$I,6,FALSE()) -> 45775 | I24: 400
A25: 22 | C25: 邬志雄 | D25: =VLOOKUP(C25,[2]在职人员信息表!$F:$U,16,FALSE) -> 152723198801254515 | E25: 矿级领导 | F25: 安全副矿长 | G25: 正经理级/副矿级 | H25: =VLOOKUP(C25,[2]任职汇总表!$D:$I,6,FALSE()) -> 45866 | I25: 400
A26: 23 | C26: 赵喜龙 | D26: =VLOOKUP(C26,[2]在职人员信息表!$F:$U,16,FALSE) -> 152723198610124814 | E26: =VLOOKUP(C26,[2]在职人员信息表!$F:$G,2,FALSE) -> 通风科 | F26: =VLOOKUP(C26,[2]在职人员信息表!$F:$H,3,FALSE) -> 矿长助理 | G26: 正经理级/副矿级 | H26: =VLOOKUP(C26,[2]任职汇总表!$D:$I,6,FALSE()) -> 45866 | I26: 400
A27: 24 | C27: 周元甲 | D27: =VLOOKUP(C27,[2]在职人员信息表!$F:$U,16,FALSE) -> 152723198410215439 | E27: =VLOOKUP(C27,[2]在职人员信息表!$F:$G,2,FALSE) -> 开发部 | F27: =VLOOKUP(C27,[2]在职人员信息表!$F:$H,3,FALSE) -> 经理 | G27: 正经理级/副矿级 | H27: =VLOOKUP(C27,[2]任职汇总表!$D:$I,6,FALSE()) -> 45881 | I27: 400 | J27: 1000
A28: 25 | C28: 石岭 | D28: =VLOOKUP(C28,[2]在职人员信息表!$F:$U,16,FALSE) -> 142232198701063831 | E28: =VLOOKUP(C28,[2]在职人员信息表!$F:$G,2,FALSE) -> 采购部 | F28: =VLOOKUP(C28,[2]在职人员信息表!$F:$H,3,FALSE) -> 经理 | G28: 正经理级/副矿级 | H28: =VLOOKUP(C28,[2]任职汇总表!$D:$I,6,FALSE()) -> 45881 | I28: 400
A29: 26 | C29: 邓志伟 | D29: =VLOOKUP(C29,[2]在职人员信息表!$F:$U,16,FALSE) -> 152325198603106029 | E29: =VLOOKUP(C29,[2]在职人员信息表!$F:$G,2,FALSE) -> 人力行政中心 | F29: =VLOOKUP(C29,[2]在职人员信息表!$F:$H,3,FALSE) -> 高级主任人力资源管理师 | G29: 正经理级/副矿级 | H29: =VLOOKUP(C29,[2]任职汇总表!$D:$I,6,FALSE()) -> 45769 | I29: 400
A30: 27 | C30: 赵乐 | D30: =VLOOKUP(C30,[2]在职人员信息表!$F:$U,16,FALSE) -> 152723198802081222 | E30: =VLOOKUP(C30,[2]在职人员信息表!$F:$G,2,FALSE) -> 人力行政中心 | F30: =VLOOKUP(C30,[2]在职人员信息表!$F:$H,3,FALSE) -> 经理 | G30: 正经理级/副矿级 | H30: =VLOOKUP(C30,[2]任职汇总表!$D:$I,6,FALSE()) -> 45664 | I30: 400
A31: 28 | C31: 李金慧 | D31: =VLOOKUP(C31,[2]在职人员信息表!$F:$U,16,FALSE) -> 130828198708180269 | E31: =VLOOKUP(C31,[2]在职人员信息表!$F:$G,2,FALSE) -> 法务监察部 | F31: =VLOOKUP(C31,[2]在职人员信息表!$F:$H,3,FALSE) -> 经理 | G31: 正经理级/副矿级 | H31: =VLOOKUP(C31,[2]任职汇总表!$D:$I,6,FALSE()) -> 45145 | I31: 400 | J31: 600
A32: 29 | C32: 郭贵清 | D32: =VLOOKUP(C32,[2]在职人员信息表!$F:$U,16,FALSE) -> 152102196412021212 | E32: =VLOOKUP(C32,[2]在职人员信息表!$F:$G,2,FALSE) -> 总工办 | F32: =VLOOKUP(C32,[2]在职人员信息表!$F:$H,3,FALSE) -> 总工办职员 | G32: 正经理级/副矿级 | H32: =VLOOKUP(C32,[2]任职汇总表!$D:$I,6,FALSE()) -> 44559 | I32: 400
A33: 30 | C33: 赵衍国 | D33: =VLOOKUP(C33,[2]在职人员信息表!$F:$U,16,FALSE) -> 370922196708141318 | E33: =VLOOKUP(C33,[2]在职人员信息表!$F:$G,2,FALSE) -> 总工办 | F33: =VLOOKUP(C33,[2]在职人员信息表!$F:$H,3,FALSE) -> 总工办职员 | G33: 正经理级/副矿级 | H33: =VLOOKUP(C33,[2]任职汇总表!$D:$I,6,FALSE()) -> 43556 | I33: 400
A34: 31 | C34: 吴运标 | D34: =VLOOKUP(C34,[2]在职人员信息表!$F:$U,16,FALSE) -> 340621197702275610 | E34: =VLOOKUP(C34,[2]在职人员信息表!$F:$G,2,FALSE) -> 总工办 | F34: =VLOOKUP(C34,[2]在职人员信息表!$F:$H,3,FALSE) -> 总工办职员 | G34: 正经理级/副矿级 | H34: =VLOOKUP(C34,[2]任职汇总表!$D:$I,6,FALSE()) -> 45289 | I34: 400
A35: 32 | C35: 白新江 | D35: =VLOOKUP(C35,[2]在职人员信息表!$F:$U,16,FALSE) -> 140224198001280630 | E35: =VLOOKUP(C35,[2]在职人员信息表!$F:$G,2,FALSE) -> 总工办 | F35: =VLOOKUP(C35,[2]在职人员信息表!$F:$H,3,FALSE) -> 总工办主任 | G35: 正经理级/副矿级 | H35: =VLOOKUP(C35,[2]任职汇总表!$D:$I,6,FALSE()) -> 45630 | I35: 400
A36: 33 | C36: 刘栓柱 | D36: =VLOOKUP(C36,[2]在职人员信息表!$F:$U,16,FALSE) -> 130521197011257013 | E36: =VLOOKUP(C36,[2]在职人员信息表!$F:$G,2,FALSE) -> 总工办 | F36: =VLOOKUP(C36,[2]在职人员信息表!$F:$H,3,FALSE) -> 总工办职员 | G36: 正经理级/副矿级 | H36: =VLOOKUP(C36,[2]任职汇总表!$D:$I,6,FALSE()) -> 45630 | I36: 400
A37: 34 | C37: 郝春红 | D37: =VLOOKUP(C37,[2]在职人员信息表!$F:$U,16,FALSE) -> 231026198311142342 | E37: =VLOOKUP(C37,[2]在职人员信息表!$F:$G,2,FALSE) -> 经营管理部 | F37: =VLOOKUP(C37,[2]在职人员信息表!$F:$H,3,FALSE) -> 经理 | G37: 正经理级/副矿级 | H37: =VLOOKUP(C37,[2]任职汇总表!$D:$I,6,FALSE()) -> 45505 | I37: 400
A38: 35 | C38: 张广振 | D38: =VLOOKUP(C38,[2]在职人员信息表!$F:$U,16,FALSE) -> 370881198111304835 | E38: =VLOOKUP(C38,[2]在职人员信息表!$F:$G,2,FALSE) -> 综采队 | F38: =VLOOKUP(C38,[2]在职人员信息表!$F:$H,3,FALSE) -> 常务副队长 | G38: 副经理级/正科级 | H38: =VLOOKUP(C38,[2]任职汇总表!$D:$I,6,FALSE()) -> 45090 | I38: 300
A39: 36 | C39: 荣启亭 | D39: =VLOOKUP(C39,[2]在职人员信息表!$F:$U,16,FALSE) -> 370983198101161832 | E39: =VLOOKUP(C39,[2]在职人员信息表!$F:$G,2,FALSE) -> 综掘队 | F39: =VLOOKUP(C39,[2]在职人员信息表!$F:$H,3,FALSE) -> 队长 | G39: 副经理级/正科级 | H39: =VLOOKUP(C39,[2]任职汇总表!$D:$I,6,FALSE()) -> 45866 | I39: 300
A40: 37 | C40: 贺伟 | D40: =VLOOKUP(C40,[2]在职人员信息表!$F:$U,16,FALSE) -> 15272319861209601X | E40: =VLOOKUP(C40,[2]在职人员信息表!$F:$G,2,FALSE) -> 安全监察科 | F40: =VLOOKUP(C40,[2]在职人员信息表!$F:$H,3,FALSE) -> 科长 | G40: 副经理级/正科级 | H40: =VLOOKUP(C40,[2]任职汇总表!$D:$I,6,FALSE()) -> 45145 | I40: 300
A41: 38 | C41: 王亮勋 | D41: =VLOOKUP(C41,[2]在职人员信息表!$F:$U,16,FALSE) -> 410622197402106035 | E41: =VLOOKUP(C41,[2]在职人员信息表!$F:$G,2,FALSE) -> 选煤厂 | F41: =VLOOKUP(C41,[2]在职人员信息表!$F:$H,3,FALSE) -> 安全副厂长 | G41: 副经理级/正科级 | H41: =VLOOKUP(C41,[2]任职汇总表!$D:$I,6,FALSE()) -> 44210 | I41: 300
...

Sheet Sheet2

Sheet 2025培训费
A1: 内蒙古准格尔旗力量煤业有限公司人员2024年员工福利档案
A2: 截至2021年XX月XX日在职员工共计XXX人（本月新入职XX人，离职XX人，XX人内部调动，XX人外部调动）。
A3: 序号 | B3: 部门 | C3: 姓名 | D3: 职务 | E3: 身份证号 | F3: 联系电话
G4: 培训服务期 | J4: 培训服务期 | M4: 培训服务期 | P4: 培训服务期 | S4: 培训服务期 | V4: 备注
G5: 开始时间 | H5: 结束时间 | I5: 金额 | J5: 开始时间 | K5: 结束时间 | L5: 金额 | M5: 开始时间 | N5: 结束时间 | O5: 金额 | P5: 开始时间 | Q5: 结束时间 | R5: 金额 | S5: 开始时间 | T5: 结束时间 | U5: 金额
A6: M10000 | B6: 李波 | C6: 公司领导 | D6: 管理岗 | E6: 130522198205272415 | F6: -
B7: 章杨
A8: M10001 | B8: 刘冠杰 | C8: 公司领导 | D8: 管理岗 | E8: 152723196312021818 | F8: -
A9: M10002 | B9: 李运成 | C9: 公司领导 | D9: 管理岗 | E9: 130503196610061234 | F9: -
A10: M10003 | B10: 奚明 | C10: 公司领导 | D10: 管理岗 | E10: 21128219830626081X | F10: -
A11: M10004 | B11: 窦发权 | C11: 公司领导 | D11: 管理岗 | E11: 370902197109021292 | F11: -
A12: M10005 | B12: 马天峰 | C12: 公司领导 | D12: 管理岗 | E12: 640204196305152033 | F12: -
A13: M10006 | B13: 李印楼 | C13: 公司领导 | D13: 管理岗 | E13: 320322197003037337 | F13: -
A14: M10007 | B14: 宋云飞 | C14: 公司领导 | D14: 管理岗 | E14: 230822198111094910 | F14: -
A15: M10008 | B15: 周洪刚 | C15: 公司领导 | D15: 管理岗 | E15: 130403196411292114 | F15: -
A16: M10011 | B16: 王震 | C16: 公司领导 | D16: 管理岗 | E16: 152723198509184812 | F16: -
A17: M10172 | B17: 李秦生 | C17: 矿级领导 | D17: 管理岗 | E17: 362329198611264574 | F17: 15847702155
A18: M10412 | B18: 杨维海 | C18: 矿级领导 | D18: 管理岗 | E18: 340403197510102439 | F18: 15847076472
A19: M10283 | B19: 郭洪亮 | C19: 矿级领导 | D19: 管理岗 | E19: 230303198407064239 | F19: 18646751172 | G19: 45826 | H19: 45828 | I19: 400 | J19: 45839 | K19: 45844 | L19: 3400
A20: M10696 | B20: 刘栓柱 | C20: 矿级领导 | D20: 管理岗 | E20: 130521197011257013 | F20: 18647722268
A21: P10726 | B21: 高翔 | C21: 矿级领导 | D21: 管理岗 | E21: 14010219810504601X | F21: 13834280786 | G21: 45755 | H21: 45761 | I21: 4695 | J21: 45830 | K21: 45835 | L21: 3452.67
A22: P10866 | B22: 王荣 | C22: 矿级领导 | D22: 管理岗 | E22: 140581198801043215 | F22: 13834939720
A23: P10572 | B23: 陈永清 | C23: 矿级领导 | D23: 管理岗 | E23: 230321197809105011 | F23: 13834494335 | G23: 45818 | H23: 45823 | I23: 3400
A24: F10133 | B24: 管云丰 | C24: 矿级领导 | D24: 管理岗 | E24: 13262419740427753X | F24: 15149539452
B25: 谈安彬 | G25: 45696 | H25: 45703 | I25: 4153.86 | J25: 45791 | K25: 45799 | L25: 4619.97
A26: F10879 | B26: 孙启明 | C26: 综采队 | D26: 管理岗 | E26: 150428198903200159 | F26: 15149739502
A27: F10789 | B27: 张广振 | C27: 综采队 | D27: 管理岗 | E27: 370881198111304835 | F27: 18754751818
A28: F10868 | B28: 杨培 | C28: 综采队 | D28: 专业技术岗 | E28: 152723198612071517 | F28: 15947364973
A29: F10571 | B29: 商好学 | C29: 综采队 | D29: 专业技术岗 | E29: 370826197111153732 | F29: 15054887907
A30: F10658 | B30: 杨肖 | C30: 综采队 | D30: 专业技术岗 | E30: 320322198908010811 | F30: 13734830459
A31: S10926 | B31: 蔡庆鑫 | C31: 综采队 | D31: 专业技术岗 | E31: 152128199611050910 | F31: 15848627873
A32: M10818 | B32: 贾云云 | C32: 综采队 | D32: 专业技术岗 | E32: 140428199405043261 | F32: 15698615326
A33: M10115 | B33: 张向辉 | C33: 综采队 | D33: 工人岗 | E33: 220881197811216011 | F33: 15947177929
A34: M10519 | B34: 薛宪伟 | C34: 综采队 | D34: 工人岗 | E34: 320322198604162517 | F34: 18247708003
A35: P10685 | B35: 张延朝 | C35: 综采队 | D35: 工人岗 | E35: 132202198001264632 | F35: 15028919688
A36: P10797 | B36: 韩志发 | C36: 综采队 | D36: 工人岗 | E36: 132224197605111657 | F36: 15289211913
A37: P10746 | B37: 雷铁柱 | C37: 综采队 | D37: 工人岗 | E37: 130822197805036231 | F37: 15233372187
... A51: P10832 | B51: 刘新 | C51: 综采队 | D51: 工人岗 | E51: 210124197404192617 | F51: 17097446118
A52: P10525 | B52: 杨纪仓 | C52: 综采队 | D52: 工人岗 | E52: 370826198403242838 | F52: 15149436941 | G52: 45663 | H52: 45667 | I52: 900
A53: P10195 | B53: 马小平 | C53: 综采队 | D53: 工人岗 | E53: 152722197911043910 | F53: 15049436437
...

Sheet 在职人员信息表（2023年电话费全部人员情况）
A1: 序号 | B1: 身份证号码 | C1: 工作单位 | D1: 人员构成 | E1: 工号 | F1: 姓名 | G1: 2022年报销 | H1: 2023年报销 | I1: 2022-2023报销合计 | J1: 工作部门 | K1: 岗位 | L1: 话费开始报销月份 | M1: 报销依据 | N1: 报销标准 | O1: 最终审批人 | P1: 是否有扫描件 | Q1: 兼职岗位/轮岗部门 | R1: 岗位类别 | S1: 级别 | T1: 人员 类别 | U1: 入职时间 | V1: 司龄 | W1: 合同类型 | X1: 性别 | Y1: 民族 | Z1: 出生日期 | AA1: 身份证地址 | AB1: 身份证号码 | AC1: 签发机关 | AD1: 身份证到期日期 | AE1: 年龄 | AF1: 政治 面貌 | AG1: 婚姻状况 | AH1: 身高（CM） | AI1: 驾驶 证 | AJ1: 血型 | AK1: 联系电话 | AL1: 紧急联系人 电话 | AM1: 最高 学历 | AN1: 毕业日期 | AO1: 毕业院校 | AP1: 专业 | AQ1: 专业技术职务名称 | AR1: 职业资格证书 | AS1: 优才类别 | AT1: 技能等级 | AU1: 劳动合同管理 | AV1: 劳动合同 开始日期 | AW1: 试用期 截止日期 | AX1: 最新 合同类型 | AY1: 最新 合同甲方 | AZ1: 最新合同 开始时间 | BA1: 最新合同 截止时间 | BB1: 最新合同 份数 | BC1: 最新合同 公章 | BD1: 最新合同 法人章 | BE1: 最新合同 签字 | BF1: 最新合同 指纹 | BG1: 其他合同 种类 | BH1: 其他合同 种类 | BI1: 备注 | BJ1: 电子 资料 | BK1: 身份证扫描件 | BL1: 职称证书扫描件 | BM1: 职业资格证扫描件 | BN1: 毕业证/学位证扫描件 | BO1: 退伍军人证扫描件 | BP1: 残疾人证扫描件 | BQ1: 档案室资料 | BR1: 档案柜 | BS1: 面试考评表 | BT1: 新员工入职单 | BU1: 个人简历 | BV1: 廉洁自律承诺书 | BW1: 入职承诺书 | BX1: 职业危害告知书 | BY1: 保密协议 | BZ1: 解除劳动合同证明 | CA1: 调动单 | CB1: 试用期考评表/转正审批表 | CC1: 职位申请表 | CD1: 人事考评审批表 | CE1: 培训协议 | CF1: 体检报告 | CG1: 其他文件 | CH1: 离职资料 | CI1: 离职申请表 | CJ1: 离职交接单 | CK1: 解除劳动合同证明 | CL1: 离职体检告知书 | CM1: 离职体检报告
A2: =IF(B2="","",ROW()-1) -> 1 | B2: =IF(AB2="","",AB2) -> 130522198205272415 | C2: 力量煤业 | D2: 公司人员 | E2: M10000 | F2: 李波 | G2: 0 | H2: 0 | I2: =G2+H2 -> 0 | J2: 公司领导 | K2: 董事长 | Q2: 2021-4-20兼任内蒙古量殖农牧业发展集团董事长； 2022-5-30任力量发展有限公司执行董事兼行政总裁； 2022-6-4兼管力量发展集团人事、行政工作； | R2: 管理岗 | S2: 董事长 | T2: 正式工 | U2: 38075 | V2: =IF(U2="","",ROUND(YEARFRAC(U2,TODAY(),1),1)) -> 22.3 | W2: 无固定期限 | X2: =IF(MOD(RIGHT(LEFT(AB2,17)),2),"男","女") -> 男 | Y2: 汉 | Z2: =MID(AB2,7,4)&"-"&MID(AB2,11,2)&"-"&MID(AB2,13,2) -> 1982-05-27 | AA2: 北京市东城区和平里中街甲7号 | AB2: 130522198205272415 | AC2: - | AD2: - | AE2: =YEAR(TODAY())-MID(AB2,7,4) -> 44 | AH2: - | AI2: - | AJ2: - | AK2: - | AL2: - | AM2: 本科 | AN2: 38169 | AO2: 北京科技大学 | AP2: 行政管理学 | AQ2: 高级经济师(人力资源管理/副高级)；中级经济师（人力资源管理/中级）；注册安全工程师（煤矿/中级） | AR2: 人力资源管理师（一级） | AV2: 39080 | AW2: 无 | AX2: 劳动合同 | AY2: 力量煤业 | AZ2: 41361 | BA2: 无固定期限 | BB2: 1 | BC2: √ | BD2: × | BE2: √ | BF2: × | BG2: 5 | BH2: 5 | BM2: √ | BN2: √ | BR2: LM-01-01 | BU2: √
A3: =IF(B3="","",ROW()-1) -> 2 | B3: =IF(AB3="","",AB3) -> 152723196312021818 | C3: 力量煤业 | D3: 公司人员 | E3: M10002 | F3: 刘冠杰 | G3: 0 | H3: 0 | I3: =G3+H3 -> 0 | J3: 公司领导 | K3: 财务总监 | Q3: 2021-9-5兼任内蒙古量蕴农牧业公司财务总监； 2021-09-08兼任集团财务常务副总监 | R3: 管理岗 | S3: 总经理级 | T3: 正式工 | U3: 43094 | V3: =IF(U3="","",ROUND(YEARFRAC(U3,TODAY(),1),1)) -> 8.5 | W3: 无劳动合同 | X3: =IF(MOD(RIGHT(LEFT(AB3,17)),2),"男","女") -> 男 | Y3: 汉 | Z3: =MID(AB3,7,4)&"-"&MID(AB3,11,2)&"-"&MID(AB3,13,2) -> 1963-12-02 | AA3: 内蒙古鄂尔多斯市准格尔旗薛家湾镇 | AB3: 152723196312021818 | AC3: - | AD3: - | AE3: =YEAR(TODAY())-MID(AB3,7,4) -> 63 | AH3: - | AI3: - | AJ3: - | AK3: - | AL3: - | AM3: 本科 | AN3: / | AO3: - | AP3: - | AV3: 43094 | AW3: 已转正 | AX3: 无 | AY3: 无 | AZ3: 无 | BA3: 无劳动合同 | BG3: 0 | BH3: 0 | BR3: LM-01-01
A4: =IF(B4="","",ROW()-1) -> 3 | B4: =IF(AB4="","",AB4) -> 130503196610061234 | C4: 力量煤业 | D4: 公司人员 | E4: M10001 | F4: 李运成 | G4: 2401.85 | H4: 0 | I4: =G4+H4 -> 2401.85 | J4: 公司领导 | K4: 总经理 | M4: 任命文件报销 | R4: 管理岗 | S4: 总经理级 | T4: 正式工 | U4: 41365 | V4: =IF(U4="","",ROUND(YEARFRAC(U4,TODAY(),1),1)) -> 13.3 | W4: 固定期限劳动合同 | X4: =IF(MOD(RIGHT(LEFT(AB4,17)),2),"男","女") -> 男 | Y4: 汉 | Z4: =MID(AB4,7,4)&"-"&MID(AB4,11,2)&"-"&MID(AB4,13,2) -> 1966-10-06 | AA4: 河北省邢台市桥西区显德汪煤矿住宅区31楼2单元12号 | AB4: 130503196610061234 | AC4: 邢台市公安局桥西分局 | AD4: 46846 | AE4: =YEAR(TODAY())-MID(AB4,7,4) -> 60 | AH4: - | AI4: - | AJ4: - | AK4: - | AL4: - | AM4: 本科 | AN4: 32509 | AO4: 山西矿业学院（现太原理工大学） | AP4: 矿井建设 | AQ4: 工程师（中级） | AV4: 41365 | AW4: 41426 | AX4: 劳动合同 | AY4: 力量煤业 | AZ4: 45017 | BA4: 46112 | BB4: 2 | BC4: √ | BD4: × | BE4: √ | BF4: × | BG4: 1 | BH4: 2 | BN4: √ | BR4: LM-01-01 | BS4: √ | BT4: √ | CC4: √ | CF4: 2018年
A5: =IF(B5="","",ROW()-1) -> 4 | B5: =IF(AB5="","",AB5) -> 21128219830626081X | C5: 力量煤业 | D5: 公司人员 | E5: M10003 | F5: 奚明 | G5: 1365.05 | H5: 0 | I5: =G5+H5 -> 1365.05 | J5: 公司领导 | K5: 常务副总经理 | M5: 任命文件报销 | R5: 管理岗 | S5: 副总级 | T5: 正式工 | U5: 43222 | V5: =IF(U5="","",ROUND(YEARFRAC(U5,TODAY(),1),1)) -> 8.2 | W5: 固定期限劳动合同 | X5: =IF(MOD(RIGHT(LEFT(AB5,17)),2),"男","女") -> 男 | Y5: 汉 | Z5: =MID(AB5,7,4)&"-"&MID(AB5,11,2)&"-"&MID(AB5,13,2) -> 1983-06-26 | AA5: 北京市朝阳区金蝉南里4号楼3单元402号 | AB5: 21128219830626081X | AC5: - | AD5: - | AE5: =YEAR(TODAY())-MID(AB5,7,4) -> 43 | AH5: - | AI5: - | AJ5: - | AK5: - | AL5: - | AM5: 研究生 | AN5: 43983 | AO5: 北京交通大学 | AP5: 工商管理 | AQ5: 高级经济师；注册造价工程师 | AR5: 皇家工料测量师RICS；项目管理师PMP | AV5: 43222 | AW5: 43282 | AX5: 劳动合同 | AY5: 力量煤业 | AZ5: 44348 | BA5: 45473 | BB5: 2 | BC5: √ | BD5: √ | BE5: √ | BF5: √ | BG5: 1 | BH5: 1 | BN5: √ | BR5: LM-01-01 | BT5: √ | BU5: √ | BY5: √ | BZ5: √ | CA5: √ | CB5: √ | CC5: √ | CF5: 2018年
A6: =IF(B6="","",ROW()-1) -> 5 | B6: =IF(AB6="","",AB6) -> 370902197109021292 | C6: 力量煤业 | D6: 公司人员 | E6: M10004 | F6: 窦发权 | G6: 3706.6 | H6: 0 | I6: =G6+H6 -> 3706.6 | J6: 公司领导 | K6: 副总经理 | M6: 任命文件报销 | Q6: 2022-4-13兼任力量发展集团有限公司集团副总工程师 | R6: 管理岗 | S6: 副总级 | T6: 正式工 | U6: 41671 | V6: =IF(U6="","",ROUND(YEARFRAC(U6,TODAY(),1),1)) -> 12.4 | W6: 固定期限劳动合同 | X6: =IF(MOD(RIGHT(LEFT(AB6,17)),2),"男","女") -> 男 | Y6: 汉 | Z6: =MID(AB6,7,4)&"-"&MID(AB6,11,2)&"-"&MID(AB6,13,2) -> 1971-09-02 | AA6: 山东省泰安市岱岳区龙潭路375号3号楼1单元501室 | AB6: 370902197109021292 | AC6: 泰安市公安局岱岳分局 | AD6: 长期 | AE6: =YEAR(TODAY())-MID(AB6,7,4) -> 55 | AH6: - | AI6: - | AJ6: - | AK6: - | AL6: - | AM6: 本科 | AN6: 34881 | AO6: 山东矿业学院 | AP6: 采矿工程 | AQ6: 工程师（采矿/高级）；注册安全工程师（煤矿/中级） | AV6: 41671 | AW6: 41730 | AX6: 劳动合同 | AY6: 力量煤业 | AZ6: 44287 | BA6: 45382 | BB6: 2 | BC6: √ | BD6: × | BE6: √ | BF6: √ | BG6: 2 | BH6: 4 | BR6: LM-01-01 | BU6: √ | CA6: √
A7: =IF(B7="","",ROW()-1) -> 6 | B7: =IF(AB7="","",AB7) -> 640204196305152033 | C7: 力量煤业 | D7: 公司人员 | E7: M10005 | F7: 马天峰 | G7: 2502.5 | H7: 0 | I7: =G7+H7 -> 2502.5 | J7: 公司领导 | K7: 副总经理 | M7: 任命文件报销 | R7: 管理岗 | S7: 副总级 | T7: 正式工 | U7: 40465 | V7: =IF(U7="","",ROUND(YEARFRAC(U7,TODAY(),1),1)) -> 15.7 | W7: 无固定期限 | X7: =IF(MOD(RIGHT(LEFT(AB7,17)),2),"男","女") -> 男 | Y7: 回 | Z7: =MID(AB7,7,4)&"-"&MID(AB7,11,2)&"-"&MID(AB7,13,2) -> 1963-05-15 | AA7: 宁夏石嘴山市惠农区矿安路北3-4-6 | AB7: 640204196305152033 | AC7: 石嘴山市公安局惠农区分局 | AD7: 长期 | AE7: =YEAR(TODAY())-MID(AB7,7,4) -> 63 | AH7: - | AI7: - | AJ7: - | AK7: - | AL7: - | AM7: 本科 | AN7: 31291 | AO7: 西安矿业学院 | AP7: 煤矿机械化 | AQ7: 工程师（机电/高级） | AV7: 40465 | AW7: 40525 | AX7: 劳动合同 | AY7: 力量煤业 | AZ7: 41196 | BA7: 无固定期限 | BB7: 2 | BC7: √ | BD7: √ | BE7: × | BF7: × | BG7: 1 | BH7: 1 | BL7: √ | BN7: √ | BR7: LM-01-01 | BS7: √ | BU7: √ | CC7: √ | CG7: 放弃缴纳公积金、社保说明
A8: =IF(B8="","",ROW()-1) -> 7 | B8: =IF(AB8="","",AB8) -> 320322197003037337 | C8: 力量煤业 | D8: 公司人员 | E8: M10006 | F8: 李印楼 | G8: 3470.55 | H8: 0 | I8: =G8+H8 -> 3470.55 | J8: 公司领导 | K8: 副总经理兼矿长 | M8: 任命文件报销 | R8: 管理岗 | S8: 副总级 | T8: 正式工 | U8: 41306 | V8: =IF(U8="","",ROUND(YEARFRAC(U8,TODAY(),1),1)) -> 13.4 | W8: 固定期限劳动合同 | X8: =IF(MOD(RIGHT(LEFT(AB8,17)),2),"男","女") -> 男 | Y8: 汉 | Z8: =MID(AB8,7,4)&"-"&MID(AB8,11,2)&"-"&MID(AB8,13,2) -> 1970-03-03 | AA8: 江苏省沛县大屯煤电徐庄风井小区433号 | AB8: 320322197003037337 | AC8: 沛县公安局 | AD8: 长期 | AE8: =YEAR(TODAY())-MID(AB8,7,4) -> 56 | AH8: - | AI8: - | AJ8: - | AK8: - | AL8: - | AM8: 大专 | AN8: 34881 | AO8: 中国矿业大学 | AP8: 机电一体化 | AQ8: 工程师（机电一体化/高级） | AV8: 41306 | AW8: 41365 | AX8: 劳动合同 | AY8: 力量煤业 | AZ8: 43922 | BA8: 46112 | BB8: 2 | BC8: √ | BD8: × | BE8: √ | BF8: √ | BG8: 2 | BH8: 3 | BL8: √ | BN8: √ | BR8: LM-01-01 | BS8: √ | BT8: √ | BU8: √ | BZ8: √ | CB8: √ | CC8: √ | CF8: 2018年 | CG8: 荣誉证书*5/工伤认定证/谈话记录
A9: =IF(B9="","",ROW()-1) -> 8 | B9: =IF(AB9="","",AB9) -> 230822198111094910 | C9: 力量煤业 | D9: 公司人员 | E9: M10007 | F9: 宋云飞 | G9: 0 | H9: 0 | I9: =G9+H9 -> 0 | J9: 公司领导 | K9: 副总经理 | Q9: 2022-11-15兼任内蒙古量蕴农业发展有限公司总经理 | R9: 管理岗 | S9: 副总级 | T9: 正式工 | U9: 41061 | V9: =IF(U9="","",ROUND(YEARFRAC(U9,TODAY(),1),1)) -> 14.1 | W9: 固定期限劳动合同 | X9: =IF(MOD(RIGHT(LEFT(AB9,17)),2),"男","女") -> 男 | Y9: 汉 | Z9: =MID(AB9,7,4)&"-"&MID(AB9,11,2)&"-"&MID(AB9,13,2) -> 1981-11-09 | AA9: 北京市朝阳区惠忠庵一号对外经济贸易大学（04研） | AB9: 230822198111094910 | AC9: - | AD9: - | AE9: =YEAR(TODAY())-MID(AB9,7,4) -> 45 | AH9: - | AI9: - | AJ9: - | AK9: - | AL9: - | AM9: 研究生 | AN9: 38899 | AO9: 对外经济贸易大学 | AP9: 技术经济及管理 | AV9: 42482 | AW9: 42542 | AX9: 劳动合同 | AY9: 力量煤业 | AZ9: 44306 | BA9: 45473 | BB9: 2 | BC9: √ | BD9: √ | BE9: √ | BF9: √ | BG9: 1 | BH9: 2 | BN9: √ | BR9: LM-01-01 | BT9: √ | BV9: √ | BW9: √ | BY9: √
A10: =IF(B10="","",ROW()-1) -> 9 | B10: =IF(AB10="","",AB10) -> 130403196411292114 | C10: 力量煤业 | D10: 公司人员 | E10: M10008 | F10: 周洪刚 | G10: 1889.2 | H10: 0 | I10: =G10+H10 -> 1889.2 | J10: 公司领导 | K10: 总经理助理兼多种经营部经理 | M10: 任命文件报销 | Q10: 2021-10-27兼任量蕴牧业发展有限公司常务副总经理 | R10: 管理岗 | S10: 副总级 | T10: 正式工 | U10: 40313 | V10: =IF(U10="","",ROUND(YEARFRAC(U10,TODAY(),1),1)) -> 16.1 | W10: 无固定期限 | X10: =IF(MOD(RIGHT(LEFT(AB10,17)),2),"男","女") -> 男 | Y10: 汉 | Z10: =MID(AB10,7,4)&"-"&MID(AB10,11,2)&"-"&MID(AB10,13,2) -> 1964-11-29 | AA10: 河北省邯郸市邯山区和平路373号9栋2单元7号 | AB10: 130403196411292114 | AC10: - | AD10: - | AE10: =YEAR(TODAY())-MID(AB10,7,4) -> 62 | AF10: 中共党员 | AG10: 已婚 | AH10: - | AI10: C1 | AJ10: O | AK10: - | AL10: - | AM10: 大专 | AN10: 40969 | AO10: 河北机电学院 | AP10: 工业经济管理 | AV10: 40313 | AW10: 40374 | AX10: 劳动合同 | AY10: 力量煤业 | AZ10: 41408 | BA10: 无固定期限 | BB10: 2 | BC10: √ | BD10: √ | BE10: √ | BF10: × | BG10: 1 | BH10: 1 | BN10: √ | BR10: LM-01-01 | BS10: √ | CC10: √ | CG10: 社保扣款及收费凭证*8
A11: =IF(B11="","",ROW()-1) -> 10 | B11: =IF(AB11="","",AB11) -> 152723198509184812 | C11: 力量煤业 | D11: 公司人员 | E11: M10010 | F11: 王震 | G11: 3445.2 | H11: 0 | I11: =G11+H11 -> 3445.2 | J11: 公司领导 | K11: 副总经理 | M11: 任命文件报销 | Q11: 2021-10-27兼任内蒙古量蕴牧业发展有限公司副总经理 | R11: 管理岗 | S11: 副总级 | T11: 正式工 | U11: 40392 | V11: =IF(U11="","",ROUND(YEARFRAC(U11,TODAY(),1),1)) -> 15.9 | W11: 无固定期限 | X11: =IF(MOD(RIGHT(LEFT(AB11,17)),2),"男","女") -> 男 | Y11: 汉 | Z11: =MID(AB11,7,4)&"-"&MID(AB11,11,2)&"-"&MID(AB11,13,2) -> 1985-09-18 | AA11: 内蒙古鄂尔多斯市准格尔旗大路镇乌兰不浪村小东社218号 | AB11: 152723198509184812 | AC11: - | AD11: - | AE11: =YEAR(TODAY())-MID(AB11,7,4) -> 41 | AF11: 群众 | AG11: 已婚 | AH11: - | AI11: C1 | AJ11: O | AK11: - | AL11: - | AM11: 大专 | AN11: / | AO11: - | AP11: 电气工程及其 自动化 | AV11: 40392 | AW11: 40756 | AX11: 劳动合同 | AY11: 力量煤业 | AZ11: 41518 | BA11: 无固定期限 | BB11: 2 | BC11: √ | BD11: × | BE11: √ | BF11: √ | BG11: 2 | BH11: 2 | BN11: √ | BR11: LM-01-01 | BS11: √ | BU11: √ | BZ11: √ | CC11: √ | CG11: 驾驶证扫描件
A12: =IF(B12="","",ROW()-1) -> 11 | B12: =IF(AB12="","",AB12) -> 362329198611264574 | C12: 力量煤业 | D12: 直接生产人员 | E12: M10111 | F12: 李秦生 | G12: 4861.83 | H12: 0 | I12: =G12+H12 -> 4861.83 | J12: 矿级领导 | K12: 总工程师 | M12: 任命文件报销 | Q12: 2022-2-26兼任力量煤业副总工程师； 2022-6-16兼任内蒙古准格尔旗力量煤业大饭铺煤矿常务副矿长 | R12: 管理岗 | S12: 高级经理级 | T12: 正式工 | U12: 40410 | V12: =IF(U12="","",ROUND(YEARFRAC(U12,TODAY(),1),1)) -> 15.9 | W12: 无固定期限 | X12: =IF(MOD(RIGHT(LEFT(AB12,17)),2),"男","女") -> 男 | Y12: 汉 | Z12: =MID(AB12,7,4)&"-"&MID(AB12,11,2)&"-"&MID(AB12,13,2) -> 1986-11-26 | AA12: 重庆市綦江区安稳镇松北路179号5单元 | AB12: 362329198611264574 | AC12: 重庆市公安局綦江分局 | AD12: 50546 | AE12: =YEAR(TODAY())-MID(AB12,7,4) -> 40 | AF12: 群众 | AG12: 已婚 | AH12: 162 | AI12: C1 | AJ12: AB | AK12: 15847702155 | AL12: 15134841667 | AM12: 本科 | AN12: 39627 | AO12: 中国矿业大学 | AP12: 采矿工程 | AQ12: 工程师（采矿工程/副高级）；注册安全工程师（中级） | AV12: 40410 | AW12: 40470 | AX12: 劳动合同 | AY12: 力量煤业 | AZ12: 41141 | BA12: 无固定期限 | BB12: 1 | BC12: √ | BD12: √ | BE12: √ | BF12: × | BG12: 1 | BH12: 1 | BL12: √ | BN12: √ | BR12: LM-01-01 | BS12: √ | BU12: √ | CA12: √ | CC12: √ | CE12: √ | CF12: 2018年 | CG12: 领取劳动合同说明
A13: =IF(B13="","",ROW()-1) -> 12 | B13: =IF(AB13="","",AB13) -> 340403197510102439 | C13: 力量煤业 | D13: 直接生产人员 | E13: M10294 | F13: 杨维海 | G13: 1738.02 | H13: 0 | I13: =G13+H13 -> 1738.02 | J13: 矿级领导 | K13: 副矿长 | M13: 任命文件报销 | R13: 管理岗 | S13: 正经理级/副矿级 | T13: 正式工 | U13: 41373 | V13: =IF(U13="","",ROUND(YEARFRAC(U13,TODAY(),1),1)) -> 13.2 | W13: 固定期限劳动合同 | X13: =IF(MOD(RIGHT(LEFT(AB13,17)),2),"男","女") -> 男 | Y13: 汉 | Z13: =MID(AB13,7,4)&"-"&MID(AB13,11,2)&"-"&MID(AB13,13,2) -> 1975-10-10 | AA13: 安徽省淮南市田家庵区安成镇石头埠村３７号 | AB13: 340403197510102439 | AC13: 淮南市公安局田家庵分局 | AD13: 46270 | AE13: =YEAR(TODAY())-MID(AB13,7,4) -> 51 | AF13: 群众 | AG13: 已婚 | AH13: 176 | AI13: C1 | AJ13: O | AK13: 15847076472 | AL13: 18248085396 | AM13: 大专（函授） | AN13: 44013 | AO13: 东北大学 | AP13: 煤矿开采技术 | AV13: 41373 | AW13: 41434 | AX13: 劳动合同 | AY13: 力量煤业 | AZ13: 44743 | BA13: 45838 | BB13: 2 | BC13: √ | BD13: √ | BE13: √ | BF13: √ | BG13: 2 | BH13: 4 | BR13: LM-01-03 | BS13: √ | BT13: √ | CB13: √ | CC13: √ | CG13: 特种作业证
A14: =IF(B14="","",ROW()-1) -> 13 | B14: =IF(AB14="","",AB14) -> 230303198407064239 | C14: 力量煤业 | D14: 直接生产人员 | E14: M10293 | F14: 郭洪亮 | G14: 2035.5 | H14: 0 | I14: =G14+H14 -> 2035.5 | J14: 矿级领导 | K14: 安全副矿长 | M14: 任命文件报销 | R14: 管理岗 | S14: 正经理级/副矿级 | T14: 正式工 | U14: 41371 | V14: =IF(U14="","",ROUND(YEARFRAC(U14,TODAY(),1),1)) -> 13.2 | W14: 固定期限劳动合同 | X14: =IF(MOD(RIGHT(LEFT(AB14,17)),2),"男","女") -> 男 | Y14: 汉 | Z14: =MID(AB14,7,4)&"-"&MID(AB14,11,2)&"-"&MID(AB14,13,2) -> 1984-07-06 | AA14: 黑龙江省鸡西市滴道区河北十四委10组 | AB14: 230303198407064239 | AC14: 鸡西市公安局滴道分局 | AD14: 49973 | AE14: =YEAR(TODAY())-MID(AB14,7,4) -> 42 | AF14: 中共党员 | AG14: 已婚 | AH14: 180 | AI14: - | AJ14: AB | AK14: 18646751172 | AL14: 15734773315 | AM14: 本科 | AN14: 39264 | AO14: 黑龙江科技学院 | AP14: 机电一体化、采矿工程 | AQ14: 工程师（）/助理工程师 | AV14: 41371 | AW14: 41432 | AX14: 劳动合同 | AY14: 力量煤业 | AZ14: 44743 | BA14: 45838 | BB14: 2 | BC14: √ | BD14: √ | BE14: √ | BF14: √ | BG14: 2 | BH14: 4 | BL14: √ | BN14: √ | BR14: LM-01-03 | BS14: √ | BT14: √ | CA14: √ | CB14: √ | CC14: √
A15: =IF(B15="","",ROW()-1) -> 14 | B15: =IF(AB15="","",AB15) -> 130521197011257013 | C15: 力量煤业 | D15: 直接生产人员 | E15: M10250 | F15: 刘栓柱 | G15: 1572.88 | H15: 0 | I15: =G15+H15 -> 1572.88 | J15: 矿级领导 | K15: 矿长助理 | M15: 任命文件报销 | R15: 管理岗 | S15: 正经理级/副矿级 | T15: 正式工 | U15: 41326 | V15: =IF(U15="","",ROUND(YEARFRAC(U15,TODAY(),1),1)) -> 13.4 | W15: 固定期限劳动合同 | X15: =IF(MOD(RIGHT(LEFT(AB15,17)),2),"男","女") -> 男 | Y15: 汉 | Z15: =MID(AB15,7,4)&"-"&MID(AB15,11,2)&"-"&MID(AB15,13,2) -> 1970-11-25 | AA15: 河北省邢台市邢台县路罗镇桃树坪村368号 | AB15: 130521197011257013 | AC15: 邢台县公安局 | AD15: 47502 | AE15: =YEAR(TODAY())-MID(AB15,7,4) -> 56 | AF15: 群众 | AG15: 已婚 | AH15: 175 | AI15: C1 | AJ15: O | AK15: 18647722268 | AL15: 15097965491 | AM15: 大专（函授） | AN15: 44022 | AO15: 东北大学 | AP15: 煤矿开采技术 | AV15: 41326 | AW15: 41385 | AX15: 劳动合同 | AY15: 力量煤业 | AZ15: 43922 | BA15: 46112 | BB15: 2 | BC15: √ | BD15: √ | BE15: √ | BF15: √ | BG15: 2 | BH15: 3 | BN15: √ | BR15: LM-01-03 | BS15: √ | BT15: √ | CB15: √ | CC15: √ | CG15: 谈话记录
A16: =IF(B16="","",ROW()-1) -> 15 | B16: =IF(AB16="","",AB16) -> 14010219810504601X | C16: 力量煤业 | D16: 直接生产人员 | E16: M11616 | F16: 高翔 | I16: =G16+H16 -> 0 | J16: 矿级领导 | K16: 生产副矿长 | R16: 管理岗 | S16: 正经理级/副矿级 | T16: 正式工 | U16: 45085 | V16: =IF(U16="","",ROUND(YEARFRAC(U16,TODAY(),1),1)) -> 3.1 | W16: 固定期限劳动合同 | X16: =IF(MOD(RIGHT(LEFT(AB16,17)),2),"男","女") -> 男 | Y16: 汉 | Z16: =MID(AB16,7,4)&"-"&MID(AB16,11,2)&"-"&MID(AB16,13,2) -> 1981-05-04 | AA16: 山西省阳泉市矿区立新区美丽家园1楼4门6号 | AB16: 14010219810504601X | AC16: 阳泉市公安局矿区分局 | AD16: 49923 | AE16: =YEAR(TODAY())-MID(AB16,7,4) -> 45 | AF16: 党员 | AG16: 已婚 | AH16: 167 | AJ16: A | AK16: 13834280786 | AL16: 13834280789 | AM16: 本科 | AN16: 2017年 | AO16: 太原理工大学 | AP16: 矿业工程 | AV16: 45085 | AW16: 45267 | AX16: 劳动合同 | AY16: 力量煤业 | AZ16: 45085 | BA16: 46203 | BB16: 2 | BC16: √ | BD16: √ | BE16: √ | BF16: √ | BG16: 0 | BH16: 0 | BK16: √ | BR16: LM-05-04 | BS16: √ | BT16: √ | BU16: √ | BV16: √ | BW16: √ | BX16: √ | BY16: √
A17: =IF(B17="","",ROW()-1) -> 16 | B17: =IF(AB17="","",AB17) -> 140581198801043215 | C17: 力量煤业 | D17: 直接生产人员 | E17: M11620 | F17: 王荣 | I17: =G17+H17 -> 0 | J17: 矿级领导 | K17: 生产副总工程师 | R17: 管理岗 | S17: 正经理级/副矿级 | T17: 正式工 | U17: 45087 | V17: =IF(U17="","",ROUND(YEARFRAC(U17,TODAY(),1),1)) -> 3.1 | W17: 固定期限劳动合同 | X17: =IF(MOD(RIGHT(LEFT(AB17,17)),2),"男","女") -> 男 | Y17: 汉 | Z17: =MID(AB17,7,4)&"-"&MID(AB17,11,2)&"-"&MID(AB17,13,2) -> 1988-01-04 | AA17: 山西省晋城市城区书院街1261号古矿单身2号楼 | AB17: 140581198801043215 | AC17: 晋城市公安局城区分局 | AD17: 50511 | AE17: =YEAR(TODAY())-MID(AB17,7,4) -> 38 | AF17: 党员 | AG17: 已婚 | AH17: 178 | AJ17: A | AK17: 13834939720 | AM17: 本科 | AN17: 2010年 | AO17: 太原理工大学 | AP17: 电气工程及其自动化 | AV17: 45087 | AW17: 45269 | AX17: 劳动合同 | AY17: 力量煤业 | AZ17: 45087 | BA17: 46203 | BB17: 2 | BC17: √ | BD17: √ | BE17: √ | BF17: √ | BG17: 0 | BH17: 0 | BK17: √ | BR17: LM-05-05 | BS17: √ | BT17: √ | BU17: √ | BV17: √ | BW17: √ | BX17: √ | BY17: √
